Workbook

Sheet 00_导入说明
A1: BIFORST 飞书多维表格导入数据包
A3: 用途 | B3: 飞书多维表格OEE/良率、数据质量、岗位化看板和主动推送概念验证
A4: 公开数据 | B4: Zenodo OEE and Downtime Dataset from Heavy Clay Manufacturing Line, Version 1.0
A5: 来源链接 | B5: https://zenodo.org/records/17855209
A6: 公开数据范围 | B6: 105条OEE班次记录；1175条停机事件；含改善前后阶段
A7: 模拟数据范围 | B7: 工单、订单物料、岗位画像、推送规则、处置任务及人工注入的数据质量问题
A8: 重要声明 | B8: 所有标注“团队模拟数据”的字段和记录均非合作企业数据，不代表任何企业真实经营情况
A9: 建议导入顺序 | B9: 01_OEE班次 → 02_停机明细 → 03_工单映射_模拟 → 04_订单物料_模拟 → 10-15_多产线模拟层 → 其余配置表
A11: 工作表 | B11: 数据性质 | C11: 主键 | D11: 关联键 | E11: 飞书用途 | F11: 备注
A12: 01_OEE班次 | B12: 公开真实+复算公式 | C12: ShiftID | D12: ShiftID | E12: OEE/良率看板 | F12: OEE复算和一致性检查
A13: 02_停机明细 | B13: 公开真实 | C13: StopEventID | D13: ShiftID | E13: 停机追溯 | F13: 与OEE按ShiftID关联
A14: 03_工单映射_模拟 | B14: 团队模拟 | C14: WorkOrderID | D14: ShiftID | E14: 把生产班次映射到演示工单 | F14: 不得解释为真实订单
A15: 04_订单物料_模拟 | B15: 团队模拟 | C15: BusinessKey | D15: WorkOrderID/EventID | E15: 供应缺口与BOM冲突 | F15: 含缺口公式
A16: 05_数据质量测试 | B16: 公开数据副本+人工注错 | C16: DQRecordID | D16: ShiftID | E16: 测试AI识别能力 | F16: ExpectedIssueType为标准答案
A17: 06_岗位画像_模拟 | B17: 团队模拟 | C17: RoleID | D17: 岗位名称 | E17: 千人千面权限/摘要 | F17: 替换演示成员即可
A18: 07_推送规则_模拟 | B18: 团队模拟 | C18: RuleID | D18: 接收岗位 | E18: 自动化触发与升级 | F18: 建议先启用高风险规则
A19: 08_处置任务_模拟 | B19: 团队模拟 | C19: TaskID | D19: EventID/WorkOrderID | E19: 任务闭环 | F19: 演示提交结果和状态变化
A20: 09_字段字典 | B20: 说明 | C20: - | D20: - | E20: 字段口径 | F20: 导入后可放入Wiki/说明书
A21: 10-15_多产线模拟层 | B21: 团队模拟 | C21: SimShiftID/SimStopEventID | D21: SourceShiftID | E21: 多产线架构与智能体协同演示 | F21: 不得解释为真实企业多产线数据
A22: 使用提醒：Zenodo页面将数据标为Open但权利栏显示作者版权。比赛展示请保留作者、DOI和来源链接；如需对外再分发或商用，请另行核对许可。
A25: --- v3 更新说明 (SIM-v2.2-20260807-20260805) ---
A26: 新增表：16_不良类型_模拟 (1575行)、17_质量冻结明细_模拟 (45行)、18_换产标准_模拟 (3行)
A27: 扩展表：02_停机明细 (+6列换产字段, 公式引用18表)、13_多产线停机_模拟 (+6列换产字段, 公式引用18表)
A28: 17表补充5列：风险等级(VLOOKUP 04表)、需要人工确认(公式)、确认状态、确认人、确认时间
A29: 16表占比采用第五类余数法，严格守恒
A30: 02/13表换产字段为Excel公式(VLOOKUP+IFERROR)，用于离线审计
A31: 导入飞书Base后需重建：换产规则ID→关联字段、标准/阈值→查找引用、超时/状态→Base公式字段
A32: 所有新增数据标注：数据性质=团队模拟数据，模拟版本=SIM-v2.2-20260807-20260805
A33: 导入顺序：01→02→03→04→05→06→07→08→09→10→11→12→13→14→15→16→17→18→19

Sheet 01_OEE班次
A1: ShiftID | B1: 阶段 | C1: 班次日期 | D1: OEE原值 | E1: 开动率 | F1: 性能率 | G1: 质量率 | H1: OEE复算 | I1: OEE一致性 | J1: 良品数 | K1: 总产量 | L1: 良率复算 | M1: 计划生产时间_秒 | N1: 计划停机_秒 | O1: 非计划停机_秒 | P1: 全速生产_秒 | Q1: 低速生产_秒 | R1: 理想生产数量 | S1: 来源链接 | T1: 数据性质
A2: SHIFT-PRE-20250922 | B2: 改善前 | C2: 45922 | D2: 0.8254 | E2: 0.8902 | F2: 0.9272 | G2: 0.9996 | H2: =E2*F2*G2 | I2: =IF(ABS(D2-H2)<=0.001,"一致","需复核") | J2: 35800 | K2: 35815 | L2: =IF(K2=0,0,J2/K2) | M2: 17884 | N2: 13111 | O2: 668 | P2: 14604 | Q2: 1317 | R2: 38626.75 | S2: https://zenodo.org/records/17855209 | T2: 公开真实生产数据
A3: SHIFT-PRE-20250923 | B3: 改善前 | C3: 45923 | D3: 0.5891 | E3: 0.6236 | F3: 0.9447 | G3: 0.9975 | H3: =E3*F3*G3 | I3: =IF(ABS(D3-H3)<=0.001,"一致","需复核") | J3: 26350 | K3: 26416 | L3: =IF(K3=0,0,J3/K3) | M3: 29700 | N3: 634 | O3: 10545 | P3: 17398 | Q3: 1123 | R3: 27961 | S3: https://zenodo.org/records/17855209 | T3: 公开真实生产数据
A4: SHIFT-PRE-20250924 | B4: 改善前 | C4: 45924 | D4: 0.7498 | E4: 0.7833 | F4: 0.9572 | G4: 0.9951 | H4: =E4*F4*G4 | I4: =IF(ABS(D4-H4)<=0.001,"一致","需复核") | J4: 21490 | K4: 21594 | L4: =IF(K4=0,0,J4/K4) | M4: 28800 | N4: 3234 | O4: 3006 | P4: 21036 | Q4: 1524 | R4: 22560 | S4: https://zenodo.org/records/17855209 | T4: 公开真实生产数据
A5: SHIFT-PRE-20250925 | B5: 改善前 | C5: 45925 | D5: 0.6546 | E5: 0.7179 | F5: 0.9118 | G5: 0.9933 | H5: =E5*F5*G5 | I5: =IF(ABS(D5-H5)<=0.001,"一致","需复核") | J5: 16700 | K5: 16812 | L5: =IF(K5=0,0,J5/K5) | M5: 24300 | N5: 7713 | O5: 4541 | P5: 15935 | Q5: 1511 | R5: 18438.533 | S5: https://zenodo.org/records/17855209 | T5: 公开真实生产数据
A6: SHIFT-PRE-20250926 | B6: 改善前 | C6: 45926 | D6: 0.7397 | E6: 0.8096 | F6: 0.926 | G6: 0.9867 | H6: =E6*F6*G6 | I6: =IF(ABS(D6-H6)<=0.001,"一致","需复核") | J6: 23000 | K6: 23310 | L6: =IF(K6=0,0,J6/K6) | M6: 22920 | N6: 5981 | O6: 3364 | P6: 17342 | Q6: 1213 | R6: 25172.8 | S6: https://zenodo.org/records/17855209 | T6: 公开真实生产数据
A7: SHIFT-PRE-20250929 | B7: 改善前 | C7: 45929 | D7: 0.6467 | E7: 0.6717 | F7: 0.9628 | G7: 0.9967 | H7: =E7*F7*G7 | I7: =IF(ABS(D7-H7)<=0.001,"一致","需复核") | J7: 46000 | K7: 46150 | L7: =IF(K7=0,0,J7/K7) | M7: 29132 | N7: 1285 | O7: 8847 | P7: 18284 | Q7: 1284 | R7: 47931.833 | S7: https://zenodo.org/records/17855209 | T7: 公开真实生产数据
A8: SHIFT-PRE-20250930 | B8: 改善前 | C8: 45930 | D8: 0.4864 | E8: 0.5234 | F8: 0.9307 | G8: 0.9985 | H8: =E8*F8*G8 | I8: =IF(ABS(D8-H8)<=0.001,"一致","需复核") | J8: 16327 | K8: 16351 | L8: =IF(K8=0,0,J8/K8) | M8: 26823 | N8: 3683 | O8: 11978 | P8: 12987 | Q8: 1052 | R8: 17568.733 | S8: https://zenodo.org/records/17855209 | T8: 公开真实生产数据
A9: SHIFT-PRE-20251002 | B9: 改善前 | C9: 45932 | D9: 0.7714 | E9: 0.8898 | F9: 0.8729 | G9: 0.9932 | H9: =E9*F9*G9 | I9: =IF(ABS(D9-H9)<=0.001,"一致","需复核") | J9: 22222 | K9: 22374 | L9: =IF(K9=0,0,J9/K9) | M9: 27006 | N9: 3562 | O9: 2107 | P9: 21138 | Q9: 2893 | R9: 25633.067 | S9: https://zenodo.org/records/17855209 | T9: 公开真实生产数据
A10: SHIFT-PRE-20251003 | B10: 改善前 | C10: 45933 | D10: 0.3383 | E10: 0.3708 | F10: 0.9221 | G10: 0.9896 | H10: =E10*F10*G10 | I10: =IF(ABS(D10-H10)<=0.001,"一致","需复核") | J10: 19727 | K10: 19935 | L10: =IF(K10=0,0,J10/K10) | M10: 27240 | N10: 1887 | O10: 15913 | P10: 9074 | Q10: 1026 | R10: 21619.333 | S10: https://zenodo.org/records/17855209 | T10: 公开真实生产数据
A11: SHIFT-PRE-20251006 | B11: 改善前 | C11: 45936 | D11: 0.7396 | E11: 0.7848 | F11: 0.9483 | G11: 0.9938 | H11: =E11*F11*G11 | I11: =IF(ABS(D11-H11)<=0.001,"一致","需复核") | J11: 54740 | K11: 55080 | L11: =IF(K11=0,0,J11/K11) | M11: 28432 | N11: 2205 | O11: 5182 | P11: 21224 | Q11: 1089 | R11: 58083.333 | S11: https://zenodo.org/records/17855209 | T11: 公开真实生产数据
A12: SHIFT-PRE-20251007 | B12: 改善前 | C12: 45937 | D12: 0.9003 | E12: 0.9238 | F12: 0.9819 | G12: 0.9925 | H12: =E12*F12*G12 | I12: =IF(ABS(D12-H12)<=0.001,"一致","需复核") | J12: 31040 | K12: 31276 | L12: =IF(K12=0,0,J12/K12) | M12: 28252 | N12: 3141 | O12: 459 | P12: 24929 | Q12: 1171 | R12: 31851 | S12: https://zenodo.org/records/17855209 | T12: 公开真实生产数据
A13: SHIFT-PRE-20251008 | B13: 改善前 | C13: 45938 | D13: 0.8304 | E13: 0.8908 | F13: 0.9354 | G13: 0.9966 | H13: =E13*F13*G13 | I13: =IF(ABS(D13-H13)<=0.001,"一致","需复核") | J13: 27771 | K13: 27867 | L13: =IF(K13=0,0,J13/K13) | M13: 22678 | N13: 7353 | O13: 1246 | P13: 18756 | Q13: 1445 | R13: 29791.133 | S13: https://zenodo.org/records/17855209 | T13: 公开真实生产数据
... A106: SHIFT-POST-20260403 | B106: 改善后 | C106: 46115 | D106: 0.66669525 | E106: 0.62813081 | F106: 1.0795872 | G106: 0.98314942 | H106: =E106*F106*G106 | I106: =IF(ABS(D106-H106)<=0.001,"一致","需复核") | J106: 6593 | K106: 6706 | L106: =IF(K106=0,0,J106/K106) | M106: 9143 | N106: 1470 | O106: 1907 | P106: 5510 | Q106: 233 | R106: 6211.6333 | S106: https://zenodo.org/records/17855209 | T106: 公开真实生产数据

Sheet 02_停机明细
A1: StopEventID | B1: ShiftID | C1: 阶段 | D1: 日期 | E1: 产品编码 | F1: 停机组 | G1: 停机原因 | H1: 停机类型 | I1: 停机位置 | J1: 操作员备注 | K1: 开始时间 | L1: 结束时间 | M1: 持续时间_分钟 | N1: 来源链接 | O1: 数据性质 | P1: 关联班次 | Q1: 班次关联状态 | R1: OEE纳入状态 | S1: 关联说明 | T1: 是否换产事件 | U1: 标准换产时间_分钟 | V1: 换产超时_分钟 | W1: 换产达标状态 | X1: 换产规则ID | Y1: 换产标准数据性质
A2: STOP-PRE-00001 | B2: SHIFT-PRE-20250922 | C2: 改善前 | D2: 45922 | E2: KK200-1 | F2: OPERATIONAL | G2: NO PRODUCTION SCHEDULE | H2: Planned - Not included in OEE | I2: EXTRUDER PRESS | J2: - | K2: 45922.469 | L2: 45922.605 | M2: 196.9 | N2: https://zenodo.org/records/17855209 | O2: 公开真实生产数据 | P2: SHIFT-PRE-20250922 | Q2: 已关联 | R2: 按班次口径判断 | T2: 否
A3: STOP-PRE-00002 | B3: SHIFT-PRE-20250922 | C3: 改善前 | D3: 45922 | E3: KK200-1 | F3: SETUPS-CHANGEOVERS | G3: WIRE ROLL REPLACEMENT | H3: Unplanned | I3: CUTTER | K3: 45922.624 | L3: 45922.626 | M3: 3.8 | N3: https://zenodo.org/records/17855209 | O3: 公开真实生产数据 | P3: SHIFT-PRE-20250922 | Q3: 已关联 | R3: 按班次口径判断 | T3: 是 | U3: =IFERROR(VLOOKUP(G3,'18_换产标准_模拟'!$B$2:$F$4,3,FALSE),"") | V3: =IFERROR(MAX(M3-U3,0),"") | W3: =IFERROR(IF(V3=0,"达标",IF(V3<=VLOOKUP(G3,'18_换产标准_模拟'!$B$2:$F$4,4,FALSE)-VLOOKUP(G3,'18_换产标准_模拟'!$B$2:$F$4,3,FALSE),"轻微超时",IF(V3<=VLOOKUP(G3,'18_换产标准_模拟'!$B$2:$F$4,5,FALSE)-VLOOKUP(G3,'18_换产标准_模拟'!$B$2:$F$4,3,FALSE),"超时","严重超时"))),"") | X3: =IFERROR(INDEX('18_换产标准_模拟'!$A$2:$A$4,MATCH(G3,'18_换产标准_模拟'!$B$2:$B$4,0)),"") | Y3: 团队模拟数据
A4: STOP-PRE-00003 | B4: SHIFT-PRE-20250922 | C4: 改善前 | D4: 45922 | E4: KK200-1 | F4: MATERIALS | G4: MANUAL BRICK HANDLING | H4: Unplanned | I4: HACKING STATION | J4: - | K4: 45922.638 | L4: 45922.643 | M4: 7.4 | N4: https://zenodo.org/records/17855209 | O4: 公开真实生产数据 | P4: SHIFT-PRE-20250922 | Q4: 已关联 | R4: 按班次口径判断 | T4: 否
A5: STOP-PRE-00004 | B5: SHIFT-PRE-20250922 | C5: 改善前 | D5: 45922 | E5: KK250 | F5: SETUPS-CHANGEOVERS | G5: MATERIAL CHANGEOVER | H5: Planned - Included in OEE | I5: EXTRUDER PRESS | J5: - | K5: 45922.743 | L5: 45922.749 | M5: 9.6 | N5: https://zenodo.org/records/17855209 | O5: 公开真实生产数据 | P5: SHIFT-PRE-20250922 | Q5: 已关联 | R5: 按班次口径判断 | T5: 是 | U5: =IFERROR(VLOOKUP(G5,'18_换产标准_模拟'!$B$2:$F$4,3,FALSE),"") | V5: =IFERROR(MAX(M5-U5,0),"") | W5: =IFERROR(IF(V5=0,"达标",IF(V5<=VLOOKUP(G5,'18_换产标准_模拟'!$B$2:$F$4,4,FALSE)-VLOOKUP(G5,'18_换产标准_模拟'!$B$2:$F$4,3,FALSE),"轻微超时",IF(V5<=VLOOKUP(G5,'18_换产标准_模拟'!$B$2:$F$4,5,FALSE)-VLOOKUP(G5,'18_换产标准_模拟'!$B$2:$F$4,3,FALSE),"超时","严重超时"))),"") | X5: =IFERROR(INDEX('18_换产标准_模拟'!$A$2:$A$4,MATCH(G5,'18_换产标准_模拟'!$B$2:$B$4,0)),"") | Y5: 团队模拟数据
A6: STOP-PRE-00005 | B6: SHIFT-PRE-20250922 | C6: 改善前 | D6: 45922 | E6: KK250 | F6: OPERATIONAL | G6: CLEANING | H6: Planned - Included in OEE | I6: EXTRUDER PRESS | J6: - | K6: 45922.804 | L6: 45922.812 | M6: 12 | N6: https://zenodo.org/records/17855209 | O6: 公开真实生产数据 | P6: SHIFT-PRE-20250922 | Q6: 已关联 | R6: 按班次口径判断 | T6: 否
A7: STOP-PRE-00006 | B7: SHIFT-PRE-20250923 | C7: 改善前 | D7: 45923 | E7: KK250 | F7: MATERIALS | G7: MANUAL BRICK HANDLING | H7: Unplanned | I7: EXTRUDER PRESS | J7: ΕΣΚΙΖΑΝ ΤΟΥΒΛΑ | K7: 45923.469 | L7: 45923.472 | M7: 5.8 | N7: https://zenodo.org/records/17855209 | O7: 公开真实生产数据 | P7: SHIFT-PRE-20250923 | Q7: 已关联 | R7: 按班次口径判断 | T7: 否
A8: STOP-PRE-00007 | B8: SHIFT-PRE-20250923 | C8: 改善前 | D8: 45923 | E8: KK250 | F8: MATERIALS | G8: MATERIAL STARVATION | H8: Unplanned | I8: SILO | J8: ΧΑΜΗΛΗ ΣΤΑΘΜΗ ΣΙΛΟ | K8: 45923.488 | L8: 45923.492 | M8: 6.4 | N8: https://zenodo.org/records/17855209 | O8: 公开真实生产数据 | P8: SHIFT-PRE-20250923 | Q8: 已关联 | R8: 按班次口径判断 | T8: 否
A9: STOP-PRE-00008 | B9: SHIFT-PRE-20250923 | C9: 改善前 | D9: 45923 | E9: 7KK25 | F9: SETUPS-CHANGEOVERS | G9: MATERIAL CHANGEOVER | H9: Planned - Included in OEE | I9: EXTRUDER PRESS | J9: - | K9: 45923.565 | L9: 45923.572 | M9: 10.6 | N9: https://zenodo.org/records/17855209 | O9: 公开真实生产数据 | P9: SHIFT-PRE-20250923 | Q9: 已关联 | R9: 按班次口径判断 | T9: 是 | U9: =IFERROR(VLOOKUP(G9,'18_换产标准_模拟'!$B$2:$F$4,3,FALSE),"") | V9: =IFERROR(MAX(M9-U9,0),"") | W9: =IFERROR(IF(V9=0,"达标",IF(V9<=VLOOKUP(G9,'18_换产标准_模拟'!$B$2:$F$4,4,FALSE)-VLOOKUP(G9,'18_换产标准_模拟'!$B$2:$F$4,3,FALSE),"轻微超时",IF(V9<=VLOOKUP(G9,'18_换产标准_模拟'!$B$2:$F$4,5,FALSE)-VLOOKUP(G9,'18_换产标准_模拟'!$B$2:$F$4,3,FALSE),"超时","严重超时"))),"") | X9: =IFERROR(INDEX('18_换产标准_模拟'!$A$2:$A$4,MATCH(G9,'18_换产标准_模拟'!$B$2:$B$4,0)),"") | Y9: 团队模拟数据
A10: STOP-PRE-00009 | B10: SHIFT-PRE-20250923 | C10: 改善前 | D10: 45923 | E10: 7KK25 | F10: MATERIALS | G10: MANUAL BRICK HANDLING | H10: Unplanned | I10: HACKING STATION | J10: ΤΟΥΒΛΑ ΕΣΠΑΖΑΝ | K10: 45923.612 | L10: 45923.64 | M10: 41.9 | N10: https://zenodo.org/records/17855209 | O10: 公开真实生产数据 | P10: SHIFT-PRE-20250923 | Q10: 已关联 | R10: 按班次口径判断 | T10: 否
A11: STOP-PRE-00010 | B11: SHIFT-PRE-20250923 | C11: 改善前 | D11: 45923 | E11: 7KK25 | F11: FAILURE | G11: MECHANICAL FAILURE | H11: Unplanned | I11: HACKING STATION | J11: ΓΩΝΙΑ ΡΟΛΟΥ | K11: 45923.647 | L11: 45923.651 | M11: 6.6 | N11: https://zenodo.org/records/17855209 | O11: 公开真实生产数据 | P11: SHIFT-PRE-20250923 | Q11: 已关联 | R11: 按班次口径判断 | T11: 否
A12: STOP-PRE-00011 | B12: SHIFT-PRE-20250923 | C12: 改善前 | D12: 45923 | E12: 7KK25 | F12: MATERIALS | G12: RACKS | H12: Unplanned | I12: HACKING STATION | J12: - | K12: 45923.654 | L12: 45923.657 | M12: 4.3 | N12: https://zenodo.org/records/17855209 | O12: 公开真实生产数据 | P12: SHIFT-PRE-20250923 | Q12: 已关联 | R12: 按班次口径判断 | T12: 否
A13: STOP-PRE-00012 | B13: SHIFT-PRE-20250923 | C13: 改善前 | D13: 45923 | E13: 7KK25 | F13: MATERIALS | G13: RACKS | H13: Unplanned | I13: HACKING STATION | J13: - | K13: 45923.664 | L13: 45923.668 | M13: 6.5 | N13: https://zenodo.org/records/17855209 | O13: 公开真实生产数据 | P13: SHIFT-PRE-20250923 | Q13: 已关联 | R13: 按班次口径判断 | T13: 否
A14: STOP-PRE-00013 | B14: SHIFT-PRE-20250923 | C14: 改善前 | D14: 45923 | E14: 7KK25 | F14: FAILURE | G14: MECHANICAL FAILURE | H14: Unplanned | I14: HACKING STATION | J14: ΓΩΝΙΑ ΡΟΛΟΥ | K14: 45923.721 | L14: 45923.73 | M14: 13.1 | N14: https://zenodo.org/records/17855209 | O14: 公开真实生产数据 | P14: SHIFT-PRE-20250923 | Q14: 已关联 | R14: 按班次口径判断 | T14: 否
A15: STOP-PRE-00014 | B15: SHIFT-PRE-20250923 | C15: 改善前 | D15: 45923 | E15: 7KK25 | F15: FAILURE | G15: MECHANICAL FAILURE | H15: Unplanned | I15: CUTTER | J15: WIRE FAILURE | K15: 45923.733 | L15: 45923.735 | M15: 3.1 | N15: https://zenodo.org/records/17855209 | O15: 公开真实生产数据 | P15: SHIFT-PRE-20250923 | Q15: 已关联 | R15: 按班次口径判断 | T15: 否
A16: STOP-PRE-00015 | B16: SHIFT-PRE-20250923 | C16: 改善前 | D16: 45923 | E16: 7KK25 | F16: MATERIALS | G16: MANUAL BRICK HANDLING | H16: Unplanned | I16: HACKING STATION | J16: ΤΟΥΒΛΑ ΕΣΠΑΖΑΝ | K16: 45923.742 | L16: 45923.767 | M16: 37.9 | N16: https://zenodo.org/records/17855209 | O16: 公开真实生产数据 | P16: SHIFT-PRE-20250923 | Q16: 已关联 | R16: 按班次口径判断 | T16: 否
A17: STOP-PRE-00016 | B17: SHIFT-PRE-20250923 | C17: 改善前 | D17: 45923 | E17: 7KK25 | F17: MATERIALS | G17: MANUAL BRICK HANDLING | H17: Unplanned | I17: EXTRUDER PRESS | J17: ΕΣΚΙΖΑΝ ΤΟΥΒΛΑ | K17: 45923.768 | L17: 45923.771 | M17: 4.3 | N17: https://zenodo.org/records/17855209 | O17: 公开真实生产数据 | P17: SHIFT-PRE-20250923 | Q17: 已关联 | R17: 按班次口径判断 | T17: 否
A18: STOP-PRE-00017 | B18: SHIFT-PRE-20250923 | C18: 改善前 | D18: 45923 | E18: 7KK25 | F18: MATERIALS | G18: RACK STARVATION | H18: Unplanned | I18: HACKING STATION | J18: ΕΞΑΓΩΓΗ ΤΕΛΑΡΩΝ ΑΠΟ ΠΑΚΑΤΑΔΟΡΟ | K18: 45923.781 | L18: 45923.812 | M18: 46 | N18: https://zenodo.org/records/17855209 | O18: 公开真实生产数据 | P18: SHIFT-PRE-20250923 | Q18: 已关联 | R18: 按班次口径判断 | T18: 否
A19: STOP-PRE-00018 | B19: SHIFT-PRE-20250924 | C19: 改善前 | D19: 45924 | E19: 7KK25 | F19: OPERATIONAL | G19: CLEANING | H19: Planned - Included in OEE | I19: EXTRUDER PRESS | J19: - | K19: 45924.469 | L19: 45924.472 | M19: 5.6 | N19: https://zenodo.org/records/17855209 | O19: 公开真实生产数据 | P19: SHIFT-PRE-20250924 | Q19: 已关联 | R19: 按班次口径判断 | T19: 否
A20: STOP-PRE-00019 | B20: SHIFT-PRE-20250924 | C20: 改善前 | D20: 45924 | E20: 7KK25 | F20: FAILURE | G20: AUTOMATION FAILURE | H20: Unplanned | I20: SILO | J20: ΔΕΝ ΕΚΚΙΝΟΥΣΕ ΤΟ ΣΙΛΟ (ΕΜΒΟΛΑ) | K20: 45924.474 | L20: 45924.482 | M20: 11.3 | N20: https://zenodo.org/records/17855209 | O20: 公开真实生产数据 | P20: SHIFT-PRE-20250924 | Q20: 已关联 | R20: 按班次口径判断 | T20: 否
A21: STOP-PRE-00020 | B21: SHIFT-PRE-20250924 | C21: 改善前 | D21: 45924 | E21: 7KK25 | F21: FAILURE | G21: AUTOMATION FAILURE | H21: Unplanned | I21: ROBOT (EXTRUDER PRESS) | J21: ΣΩΛΗΝΑΚΙ ΤΟΥ ΑΕΡΑ | K21: 45924.506 | L21: 45924.515 | M21: 12.1 | N21: https://zenodo.org/records/17855209 | O21: 公开真实生产数据 | P21: SHIFT-PRE-20250924 | Q21: 已关联 | R21: 按班次口径判断 | T21: 否
... A23: STOP-PRE-00022 | B23: SHIFT-PRE-20250924 | C23: 改善前 | D23: 45924 | E23: 7KK25 | F23: MATERIALS | G23: KILN CAR STARVATION | H23: Unplanned | I23: HACKING STATION | J23: ΔΕΝ ΕΠΙΑΝΕ ΤΟ ΒΑΓΟΝΙ Ο ΩΘΗΤΗΡΑΣ | K23: 45924.597 | L23: 45924.608 | M23: 15.4 | N23: https://zenodo.org/records/17855209 | O23: 公开真实生产数据 | P23: SHIFT-PRE-20250924 | Q23: 已关联 | R23: 按班次口径判断 | T23: 否
A24: STOP-PRE-00023 | B24: SHIFT-PRE-20250924 | C24: 改善前 | D24: 45924 | E24: 9KK30 | F24: SETUPS-CHANGEOVERS | G24: MATERIAL CHANGEOVER | H24: Planned - Included in OEE | I24: EXTRUDER PRESS | J24: - | K24: 45924.622 | L24: 45924.629 | M24: 11.3 | N24: https://zenodo.org/records/17855209 | O24: 公开真实生产数据 | P24: SHIFT-PRE-20250924 | Q24: 已关联 | R24: 按班次口径判断 | T24: 是 | U24: =IFERROR(VLOOKUP(G24,'18_换产标准_模拟'!$B$2:$F$4,3,FALSE),"") | V24: =IFERROR(MAX(M24-U24,0),"") | W24: =IFERROR(IF(V24=0,"达标",IF(V24<=VLOOKUP(G24,'18_换产标准_模拟'!$B$2:$F$4,4,FALSE)-VLOOKUP(G24,'18_换产标准_模拟'!$B$2:$F$4,3,FALSE),"轻微超时",IF(V24<=VLOOKUP(G24,'18_换产标准_模拟'!$B$2:$F$4,5,FALSE)-VLOOKUP(G24,'18_换产标准_模拟'!$B$2:$F$4,3,FALSE),"超时","严重超时"))),"") | X24: =IFERROR(INDEX('18_换产标准_模拟'!$A$2:$A$4,MATCH(G24,'18_换产标准_模拟'!$B$2:$B$4,0)),"") | Y24: 团队模拟数据
A25: STOP-PRE-00024 | B25: SHIFT-PRE-20250924 | C25: 改善前 | D25: 45924 | E25: 9KK30 | F25: FAILURE | G25: MECHANICAL FAILURE | H25: Unplanned | I25: CUTTER | J25: WIRE FAILURE | K25: 45924.717 | L25: 45924.721 | M25: 6.7 | N25: https://zenodo.org/records/17855209 | O25: 公开真实生产数据 | P25: SHIFT-PRE-20250924 | Q25: 已关联 | R25: 按班次口径判断 | T25: 否
A26: STOP-PRE-00025 | B26: SHIFT-PRE-20250924 | C26: 改善前 | D26: 45924 | E26: 9KK30 | F26: OPERATIONAL | G26: CLEANING | H26: Planned - Included in OEE | I26: EXTRUDER PRESS | J26: - | K26: 45924.776 | L26: 45924.799 | M26: 32.9 | N26: https://zenodo.org/records/17855209 | O26: 公开真实生产数据 | P26: SHIFT-PRE-20250924 | Q26: 已关联 | R26: 按班次口径判断 | T26: 否
A27: STOP-PRE-00026 | B27: SHIFT-PRE-20250924 | C27: 改善前 | D27: 45924 | E27: 9KK30 | F27: OPERATIONAL | G27: CLEANING | H27: Planned - Included in OEE | I27: ROBOT (EXTRUDER PRESS) | J27: - | K27: 45924.799 | L27: 45924.802 | M27: 4 | N27: https://zenodo.org/records/17855209 | O27: 公开真实生产数据 | P27: SHIFT-PRE-20250924 | Q27: 已关联 | R27: 按班次口径判断 | T27: 否
A28: STOP-PRE-00027 | B28: SHIFT-PRE-20250925 | C28: 改善前 | D28: 45925 | E28: 9KK30 | F28: OPERATIONAL | G28: CLEANING | H28: Planned - Included in OEE | I28: EXTRUDER PRESS | J28: - | K28: 45925.469 | L28: 45925.472 | M28: 4.4 | N28: https://zenodo.org/records/17855209 | O28: 公开真实生产数据 | P28: SHIFT-PRE-20250925 | Q28: 已关联 | R28: 按班次口径判断 | T28: 否
A29: STOP-PRE-00028 | B29: SHIFT-PRE-20250925 | C29: 改善前 | D29: 45925 | E29: 9KK25 | F29: SETUPS-CHANGEOVERS | G29: MATERIAL CHANGEOVER | H29: Planned - Included in OEE | I29: EXTRUDER PRESS | J29: - | K29: 45925.501 | L29: 45925.514 | M29: 18.5 | N29: https://zenodo.org/records/17855209 | O29: 公开真实生产数据 | P29: SHIFT-PRE-20250925 | Q29: 已关联 | R29: 按班次口径判断 | T29: 是 | U29: =IFERROR(VLOOKUP(G29,'18_换产标准_模拟'!$B$2:$F$4,3,FALSE),"") | V29: =IFERROR(MAX(M29-U29,0),"") | W29: =IFERROR(IF(V29=0,"达标",IF(V29<=VLOOKUP(G29,'18_换产标准_模拟'!$B$2:$F$4,4,FALSE)-VLOOKUP(G29,'18_换产标准_模拟'!$B$2:$F$4,3,FALSE),"轻微超时",IF(V29<=VLOOKUP(G29,'18_换产标准_模拟'!$B$2:$F$4,5,FALSE)-VLOOKUP(G29,'18_换产标准_模拟'!$B$2:$F$4,3,FALSE),"超时","严重超时"))),"") | X29: =IFERROR(INDEX('18_换产标准_模拟'!$A$2:$A$4,MATCH(G29,'18_换产标准_模拟'!$B$2:$B$4,0)),"") | Y29: 团队模拟数据
A30: STOP-PRE-00029 | B30: SHIFT-PRE-20250925 | C30: 改善前 | D30: 45925 | E30: 9KK25 | F30: MATERIALS | G30: RACK STARVATION | H30: Unplanned | I30: DRYER | J30: ΔΕΝ ΦΟΡΤΩΣΕ ΣΩΣΤΑ ΤΟ ΤΕΛΑΡΟ Ο ΜΕΤΑΦΟΡΕΑΣ | K30: 45925.54 | L30: 45925.547 | M30: 10.9 | N30: https://zenodo.org/records/17855209 | O30: 公开真实生产数据 | P30: SHIFT-PRE-20250925 | Q30: 已关联 | R30: 按班次口径判断 | T30: 否
A31: STOP-PRE-00030 | B31: SHIFT-PRE-20250925 | C31: 改善前 | D31: 45925 | E31: 9KK25 | F31: MATERIALS | G31: RACK STARVATION | H31: Unplanned | I31: HACKING STATION | J31: ΑΝΑΜΟΝΗ ΤΕΛΑΡΩΝ | K31: 45925.567 | L31: 45925.569 | M31: 4.7 | N31: https://zenodo.org/records/17855209 | O31: 公开真实生产数据 | P31: SHIFT-PRE-20250925 | Q31: 已关联 | R31: 按班次口径判断 | T31: 否
A32: STOP-PRE-00031 | B32: SHIFT-PRE-20250925 | C32: 改善前 | D32: 45925 | E32: 9KK25 | F32: FAILURE | G32: MECHANICAL FAILURE | H32: Unplanned | I32: HACKING STATION | J32: ΚΑΔΕΝΕΣ ΜΕΤΑΦΟΡΑΣ ΤΟΥΒΛΩΝ | K32: 45925.58 | L32: 45925.61 | M32: 43.8 | N32: https://zenodo.org/records/17855209 | O32: 公开真实生产数据 | P32: SHIFT-PRE-20250925 | Q32: 已关联 | R32: 按班次口径判断 | T32: 否
A33: STOP-PRE-00032 | B33: SHIFT-PRE-20250925 | C33: 改善前 | D33: 45925 | E33: 9KK25 | F33: MATERIALS | G33: RACK STARVATION | H33: Unplanned | I33: HACKING STATION | J33: ΑΝΑΜΟΝΗ ΤΕΛΑΡΩΝ | K33: 45925.625 | L33: 45925.627 | M33: 3.7 | N33: https://zenodo.org/records/17855209 | O33: 公开真实生产数据 | P33: SHIFT-PRE-20250925 | Q33: 已关联 | R33: 按班次口径判断 | T33: 否
A34: STOP-PRE-00033 | B34: SHIFT-PRE-20250925 | C34: 改善前 | D34: 45925 | E34: 9KK25 | F34: MATERIALS | G34: RACK STARVATION | H34: Unplanned | I34: HACKING STATION | J34: ΑΝΑΜΟΝΗ ΤΕΛΑΡΩΝ | K34: 45925.634 | L34: 45925.637 | M34: 4.3 | N34: https://zenodo.org/records/17855209 | O34: 公开真实生产数据 | P34: SHIFT-PRE-20250925 | Q34: 已关联 | R34: 按班次口径判断 | T34: 否
A35: STOP-PRE-00034 | B35: SHIFT-PRE-20250925 | C35: 改善前 | D35: 45925 | E35: 9KK25 | F35: FAILURE | G35: AUTOMATION FAILURE | H35: Unplanned | I35: HACKING STATION | J35: ΑΙΣΘΗΤΗΡΑΣ (ΜΑΤΙ) | K35: 45925.651 | L35: 45925.656 | M35: 8.4 | N35: https://zenodo.org/records/17855209 | O35: 公开真实生产数据 | P35: SHIFT-PRE-20250925 | Q35: 已关联 | R35: 按班次口径判断 | T35: 否
A36: STOP-PRE-00035 | B36: SHIFT-PRE-20250925 | C36: 改善前 | D36: 45925 | E36: 9KK25 | F36: SETUPS-CHANGEOVERS | G36: MATERIAL CHANGEOVER | H36: Planned - Included in OEE | I36: HACKING STATION | J36: - | K36: 45925.678 | L36: 45925.688 | M36: 15.7 | N36: https://zenodo.org/records/17855209 | O36: 公开真实生产数据 | P36: SHIFT-PRE-20250925 | Q36: 已关联 | R36: 按班次口径判断 | T36: 是 | U36: =IFERROR(VLOOKUP(G36,'18_换产标准_模拟'!$B$2:$F$4,3,FALSE),"") | V36: =IFERROR(MAX(M36-U36,0),"") | W36: =IFERROR(IF(V36=0,"达标",IF(V36<=VLOOKUP(G36,'18_换产标准_模拟'!$B$2:$F$4,4,FALSE)-VLOOKUP(G36,'18_换产标准_模拟'!$B$2:$F$4,3,FALSE),"轻微超时",IF(V36<=VLOOKUP(G36,'18_换产标准_模拟'!$B$2:$F$4,5,FALSE)-VLOOKUP(G36,'18_换产标准_模拟'!$B$2:$F$4,3,FALSE),"超时","严重超时"))),"") | X36: =IFERROR(INDEX('18_换产标准_模拟'!$A$2:$A$4,MATCH(G36,'18_换产标准_模拟'!$B$2:$B$4,0)),"") | Y36: 团队模拟数据
A37: STOP-PRE-00036 | B37: SHIFT-PRE-20250925 | C37: 改善前 | D37: 45925 | E37: 9KK25 | F37: OPERATIONAL | G37: NO PRODUCTION SCHEDULE | H37: Planned - Not included in OEE | I37: - | J37: ΔΕΝ ΕΙΧΕ ΞΕΡΑ ΤΟΥΒΛΑ | K37: 45925.75 | L37: 45925.812 | M37: 90 | N37: https://zenodo.org/records/17855209 | O37: 公开真实生产数据 | P37: SHIFT-PRE-20250925 | Q37: 已关联 | R37: 按班次口径判断 | T37: 否
A38: STOP-PRE-00037 | B38: SHIFT-PRE-20250926 | C38: 改善前 | D38: 45926 | E38: 9KK25 | F38: FAILURE | G38: AUTOMATION FAILURE | H38: Unplanned | I38: SILO | J38: ΔΕΝ ΕΚΚΙΝΟΥΣΕ ΤΟ ΣΙΛΟ (ΕΜΒΟΛΑ) | K38: 45926.477 | L38: 45926.483 | M38: 9.3 | N38: https://zenodo.org/records/17855209 | O38: 公开真实生产数据 | P38: SHIFT-PRE-20250926 | Q38: 已关联 | R38: 按班次口径判断 | T38: 否
A39: STOP-PRE-00038 | B39: SHIFT-PRE-20250926 | C39: 改善前 | D39: 45926 | E39: 9KK25 | F39: MATERIALS | G39: MANUAL BRICK HANDLING | H39: Unplanned | I39: HACKING STATION | J39: ΣΠΑΣΜΕΝΑ ΤΟΥΒΛΑ | K39: 45926.595 | L39: 45926.6 | M39: 7.4 | N39: https://zenodo.org/records/17855209 | O39: 公开真实生产数据 | P39: SHIFT-PRE-20250926 | Q39: 已关联 | R39: 按班次口径判断 | T39: 否
A40: STOP-PRE-00039 | B40: SHIFT-PRE-20250926 | C40: 改善前 | D40: 45926 | E40: 9KK25 | F40: MATERIALS | G40: MANUAL BRICK HANDLING | H40: Unplanned | I40: HACKING STATION | J40: ΣΠΑΣΜΕΝΑ ΤΟΥΒΛΑ | K40: 45926.615 | L40: 45926.62 | M40: 8.7 | N40: https://zenodo.org/records/17855209 | O40: 公开真实生产数据 | P40: SHIFT-PRE-20250926 | Q40: 已关联 | R40: 按班次口径判断 | T40: 否
A41: STOP-PRE-00040 | B41: SHIFT-PRE-20250926 | C41: 改善前 | D41: 45926 | E41: 9KK25 | F41: FAILURE | G41: OTHER FAILURE | H41: Unplanned | I41: PACKAGING | J41: ΕΣΚΙΖΕ ΤΟ ΦΙΛΜ | K41: 45926.656 | L41: 45926.666 | M41: 15.5 | N41: https://zenodo.org/records/17855209 | O41: 公开真实生产数据 | P41: SHIFT-PRE-20250926 | Q41: 已关联 | R41: 按班次口径判断 | T41: 否
...

Sheet 03_工单映射_模拟
A1: WorkOrderID | B1: ShiftID | C1: OrderNo | D1: 演示产品 | E1: LineID | F1: 生产日期 | G1: 计划数量 | H1: 实际数量 | I1: 良品数量 | J1: 需求日期 | K1: 风险等级 | L1: 数据性质 | M1: 生成说明
A2: WO-20250922-001 | B2: SHIFT-PRE-20250922 | C2: SO-2401 | D2: VR-X1 | E2: LINE-R01 | F2: 45922 | G2: 800 | H2: 660 | I2: 660 | J2: 45924 | K2: 中 | L2: 团队模拟数据 | M2: 公开OEE数据仅来自一条真实产线，统一标记LINE-R01；多产线横向演示请使用10-15模拟层
A3: WO-20250923-002 | B3: SHIFT-PRE-20250923 | C3: SO-2402 | D3: AR-X2 | E3: LINE-R01 | F3: 45923 | G3: 900 | H3: 530 | I3: 529 | J3: 45925 | K3: 高 | L3: 团队模拟数据 | M3: 公开OEE数据仅来自一条真实产线，统一标记LINE-R01；多产线横向演示请使用10-15模拟层
A4: WO-20250924-003 | B4: SHIFT-PRE-20250924 | C4: SO-2403 | D4: AUDIO-X3 | E4: LINE-R01 | F4: 45924 | G4: 1000 | H4: 750 | I4: 746 | J4: 45926 | K4: 高 | L4: 团队模拟数据 | M4: 公开OEE数据仅来自一条真实产线，统一标记LINE-R01；多产线横向演示请使用10-15模拟层
A5: WO-20250925-004 | B5: SHIFT-PRE-20250925 | C5: SO-2404 | D5: VR-X1 | E5: LINE-R01 | F5: 45925 | G5: 1100 | H5: 720 | I5: 715 | J5: 45927 | K5: 高 | L5: 团队模拟数据 | M5: 公开OEE数据仅来自一条真实产线，统一标记LINE-R01；多产线横向演示请使用10-15模拟层
A6: WO-20250926-005 | B6: SHIFT-PRE-20250926 | C6: SO-2405 | D6: AR-X2 | E6: LINE-R01 | F6: 45926 | G6: 1200 | H6: 900 | I6: 888 | J6: 45928 | K6: 高 | L6: 团队模拟数据 | M6: 公开OEE数据仅来自一条真实产线，统一标记LINE-R01；多产线横向演示请使用10-15模拟层
A7: WO-20250929-006 | B7: SHIFT-PRE-20250929 | C7: SO-2406 | D7: AUDIO-X3 | E7: LINE-R01 | F7: 45929 | G7: 800 | H7: 517 | I7: 515 | J7: 45931 | K7: 高 | L7: 团队模拟数据 | M7: 公开OEE数据仅来自一条真实产线，统一标记LINE-R01；多产线横向演示请使用10-15模拟层
A8: WO-20250930-007 | B8: SHIFT-PRE-20250930 | C8: SO-2407 | D8: VR-X1 | E8: LINE-R01 | F8: 45930 | G8: 900 | H8: 438 | I8: 437 | J8: 45932 | K8: 高 | L8: 团队模拟数据 | M8: 公开OEE数据仅来自一条真实产线，统一标记LINE-R01；多产线横向演示请使用10-15模拟层
A9: WO-20251002-008 | B9: SHIFT-PRE-20251002 | C9: SO-2408 | D9: AR-X2 | E9: LINE-R01 | F9: 45932 | G9: 1000 | H9: 777 | I9: 772 | J9: 45934 | K9: 中 | L9: 团队模拟数据 | M9: 公开OEE数据仅来自一条真实产线，统一标记LINE-R01；多产线横向演示请使用10-15模拟层
A10: WO-20251003-009 | B10: SHIFT-PRE-20251003 | C10: SO-2409 | D10: AUDIO-X3 | E10: LINE-R01 | F10: 45933 | G10: 1100 | H10: 376 | I10: 372 | J10: 45935 | K10: 高 | L10: 团队模拟数据 | M10: 公开OEE数据仅来自一条真实产线，统一标记LINE-R01；多产线横向演示请使用10-15模拟层
A11: WO-20251006-010 | B11: SHIFT-PRE-20251006 | C11: SO-2410 | D11: VR-X1 | E11: LINE-R01 | F11: 45936 | G11: 1200 | H11: 893 | I11: 887 | J11: 45938 | K11: 高 | L11: 团队模拟数据 | M11: 公开OEE数据仅来自一条真实产线，统一标记LINE-R01；多产线横向演示请使用10-15模拟层
A12: WO-20251007-011 | B12: SHIFT-PRE-20251007 | C12: SO-2411 | D12: AR-X2 | E12: LINE-R01 | F12: 45937 | G12: 800 | H12: 726 | I12: 721 | J12: 45939 | K12: 低 | L12: 团队模拟数据 | M12: 公开OEE数据仅来自一条真实产线，统一标记LINE-R01；多产线横向演示请使用10-15模拟层
A13: WO-20251008-012 | B13: SHIFT-PRE-20251008 | C13: SO-2412 | D13: AUDIO-X3 | E13: LINE-R01 | F13: 45938 | G13: 900 | H13: 750 | I13: 747 | J13: 45940 | K13: 中 | L13: 团队模拟数据 | M13: 公开OEE数据仅来自一条真实产线，统一标记LINE-R01；多产线横向演示请使用10-15模拟层
... A106: WO-20260403-105 | B106: SHIFT-POST-20260403 | C106: SO-2505 | D106: AUDIO-X3 | E106: LINE-R01 | F106: 46115 | G106: 1200 | H106: 814 | I106: 800 | J106: 46117 | K106: 高 | L106: 团队模拟数据 | M106: 公开OEE数据仅来自一条真实产线，统一标记LINE-R01；多产线横向演示请使用10-15模拟层

Sheet 04_订单物料_模拟
A1: BusinessKey | B1: EventID | C1: WorkOrderID | D1: OrderNo | E1: 订单行 | F1: 物料编码 | G1: 物料名称 | H1: 需求日期 | I1: 计划数量 | J1: BOM用量 | K1: 已领料 | L1: 现有库存 | M1: 已占用 | N1: 质量冻结 | O1: 需求日前确认到货 | P1: 需求量 | Q1: 需求日前可用量 | R1: 物料缺口 | S1: ERP承诺日期 | T1: SRM承诺日期 | U1: 日期冲突 | V1: 订单BOM版本 | W1: 工单BOM版本 | X1: BOM冲突 | Y1: 风险等级 | Z1: 数据性质 | AA1: 生成说明
A2: SO-2401-1-M-DISPLAY | B2: EVT-0001 | C2: WO-20250922-001 | D2: SO-2401 | E2: 1 | F2: M-DISPLAY | G2: 显示模组 | H2: 45924 | I2: 800 | J2: 1 | K2: 0 | L2: 584 | M2: 64 | N2: 80 | O2: 160 | P2: =MAX(0,I2*J2-K2) | Q2: =MAX(0,L2-N2-M2+O2) | R2: =MAX(0,P2-Q2) | S2: 45923 | T2: 45925 | U2: =IF(S2=T2,"一致","冲突") | V2: V3 | W2: V3 | X2: =IF(V2=W2,"一致","冲突") | Y2: =IF(OR(R2>0,U2="冲突",X2="冲突"),"高","低") | Z2: 团队模拟数据 | AA2: 依据业务规则生成，用于演示订单/BOM/库存/供应承诺闭环
A3: SO-2401-2-M-PCBA | B3: EVT-0001 | C3: WO-20250922-001 | D3: SO-2401 | E3: 2 | F3: M-PCBA | G3: 主板组件 | H3: 45924 | I3: 800 | J3: 1 | K3: 0 | L3: 864 | M3: 64 | N3: 0 | O3: 0 | P3: =MAX(0,I3*J3-K3) | Q3: =MAX(0,L3-N3-M3+O3) | R3: =MAX(0,P3-Q3) | S3: 45923 | T3: 45923 | U3: =IF(S3=T3,"一致","冲突") | V3: V3 | W3: V2 | X3: =IF(V3=W3,"一致","冲突") | Y3: =IF(OR(R3>0,U3="冲突",X3="冲突"),"高","低") | Z3: 团队模拟数据 | AA3: 依据业务规则生成，用于演示订单/BOM/库存/供应承诺闭环
A4: SO-2401-3-M-HOUSING | B4: EVT-0001 | C4: WO-20250922-001 | D4: SO-2401 | E4: 3 | F4: M-HOUSING | G4: 结构件 | H4: 45924 | I4: 800 | J4: 2 | K4: 0 | L4: 1728 | M4: 128 | N4: 0 | O4: 0 | P4: =MAX(0,I4*J4-K4) | Q4: =MAX(0,L4-N4-M4+O4) | R4: =MAX(0,P4-Q4) | S4: 45923 | T4: 45923 | U4: =IF(S4=T4,"一致","冲突") | V4: V3 | W4: V3 | X4: =IF(V4=W4,"一致","冲突") | Y4: =IF(OR(R4>0,U4="冲突",X4="冲突"),"高","低") | Z4: 团队模拟数据 | AA4: 依据业务规则生成，用于演示订单/BOM/库存/供应承诺闭环
A5: SO-2402-1-M-DISPLAY | B5: EVT-0002 | C5: WO-20250923-002 | D5: SO-2402 | E5: 1 | F5: M-DISPLAY | G5: 显示模组 | H5: 45925 | I5: 900 | J5: 1 | K5: 0 | L5: 972 | M5: 72 | N5: 0 | O5: 0 | P5: =MAX(0,I5*J5-K5) | Q5: =MAX(0,L5-N5-M5+O5) | R5: =MAX(0,P5-Q5) | S5: 45924 | T5: 45924 | U5: =IF(S5=T5,"一致","冲突") | V5: V3 | W5: V3 | X5: =IF(V5=W5,"一致","冲突") | Y5: =IF(OR(R5>0,U5="冲突",X5="冲突"),"高","低") | Z5: 团队模拟数据 | AA5: 依据业务规则生成，用于演示订单/BOM/库存/供应承诺闭环
A6: SO-2402-2-M-PCBA | B6: EVT-0002 | C6: WO-20250923-002 | D6: SO-2402 | E6: 2 | F6: M-PCBA | G6: 主板组件 | H6: 45925 | I6: 900 | J6: 1 | K6: 0 | L6: 972 | M6: 72 | N6: 0 | O6: 0 | P6: =MAX(0,I6*J6-K6) | Q6: =MAX(0,L6-N6-M6+O6) | R6: =MAX(0,P6-Q6) | S6: 45924 | T6: 45924 | U6: =IF(S6=T6,"一致","冲突") | V6: V3 | W6: V3 | X6: =IF(V6=W6,"一致","冲突") | Y6: =IF(OR(R6>0,U6="冲突",X6="冲突"),"高","低") | Z6: 团队模拟数据 | AA6: 依据业务规则生成，用于演示订单/BOM/库存/供应承诺闭环
A7: SO-2402-3-M-HOUSING | B7: EVT-0002 | C7: WO-20250923-002 | D7: SO-2402 | E7: 3 | F7: M-HOUSING | G7: 结构件 | H7: 45925 | I7: 900 | J7: 2 | K7: 0 | L7: 1944 | M7: 144 | N7: 0 | O7: 0 | P7: =MAX(0,I7*J7-K7) | Q7: =MAX(0,L7-N7-M7+O7) | R7: =MAX(0,P7-Q7) | S7: 45924 | T7: 45924 | U7: =IF(S7=T7,"一致","冲突") | V7: V3 | W7: V3 | X7: =IF(V7=W7,"一致","冲突") | Y7: =IF(OR(R7>0,U7="冲突",X7="冲突"),"高","低") | Z7: 团队模拟数据 | AA7: 依据业务规则生成，用于演示订单/BOM/库存/供应承诺闭环
A8: SO-2403-1-M-DISPLAY | B8: EVT-0003 | C8: WO-20250924-003 | D8: SO-2403 | E8: 1 | F8: M-DISPLAY | G8: 显示模组 | H8: 45926 | I8: 1000 | J8: 1 | K8: 0 | L8: 1080 | M8: 80 | N8: 0 | O8: 0 | P8: =MAX(0,I8*J8-K8) | Q8: =MAX(0,L8-N8-M8+O8) | R8: =MAX(0,P8-Q8) | S8: 45925 | T8: 45925 | U8: =IF(S8=T8,"一致","冲突") | V8: V3 | W8: V3 | X8: =IF(V8=W8,"一致","冲突") | Y8: =IF(OR(R8>0,U8="冲突",X8="冲突"),"高","低") | Z8: 团队模拟数据 | AA8: 依据业务规则生成，用于演示订单/BOM/库存/供应承诺闭环
A9: SO-2403-2-M-PCBA | B9: EVT-0003 | C9: WO-20250924-003 | D9: SO-2403 | E9: 2 | F9: M-PCBA | G9: 主板组件 | H9: 45926 | I9: 1000 | J9: 1 | K9: 0 | L9: 1080 | M9: 80 | N9: 0 | O9: 0 | P9: =MAX(0,I9*J9-K9) | Q9: =MAX(0,L9-N9-M9+O9) | R9: =MAX(0,P9-Q9) | S9: 45925 | T9: 45925 | U9: =IF(S9=T9,"一致","冲突") | V9: V3 | W9: V3 | X9: =IF(V9=W9,"一致","冲突") | Y9: =IF(OR(R9>0,U9="冲突",X9="冲突"),"高","低") | Z9: 团队模拟数据 | AA9: 依据业务规则生成，用于演示订单/BOM/库存/供应承诺闭环
A10: SO-2403-3-M-HOUSING | B10: EVT-0003 | C10: WO-20250924-003 | D10: SO-2403 | E10: 3 | F10: M-HOUSING | G10: 结构件 | H10: 45926 | I10: 1000 | J10: 2 | K10: 0 | L10: 1660 | M10: 160 | N10: 0 | O10: 0 | P10: =MAX(0,I10*J10-K10) | Q10: =MAX(0,L10-N10-M10+O10) | R10: =MAX(0,P10-Q10) | S10: 45925 | T10: 45925 | U10: =IF(S10=T10,"一致","冲突") | V10: V3 | W10: V3 | X10: =IF(V10=W10,"一致","冲突") | Y10: =IF(OR(R10>0,U10="冲突",X10="冲突"),"高","低") | Z10: 团队模拟数据 | AA10: 依据业务规则生成，用于演示订单/BOM/库存/供应承诺闭环
A11: SO-2404-1-M-DISPLAY | B11: EVT-0004 | C11: WO-20250925-004 | D11: SO-2404 | E11: 1 | F11: M-DISPLAY | G11: 显示模组 | H11: 45927 | I11: 1100 | J11: 1 | K11: 0 | L11: 1188 | M11: 88 | N11: 0 | O11: 0 | P11: =MAX(0,I11*J11-K11) | Q11: =MAX(0,L11-N11-M11+O11) | R11: =MAX(0,P11-Q11) | S11: 45926 | T11: 45926 | U11: =IF(S11=T11,"一致","冲突") | V11: V3 | W11: V3 | X11: =IF(V11=W11,"一致","冲突") | Y11: =IF(OR(R11>0,U11="冲突",X11="冲突"),"高","低") | Z11: 团队模拟数据 | AA11: 依据业务规则生成，用于演示订单/BOM/库存/供应承诺闭环
A12: SO-2404-2-M-PCBA | B12: EVT-0004 | C12: WO-20250925-004 | D12: SO-2404 | E12: 2 | F12: M-PCBA | G12: 主板组件 | H12: 45927 | I12: 1100 | J12: 1 | K12: 0 | L12: 913 | M12: 88 | N12: 0 | O12: 0 | P12: =MAX(0,I12*J12-K12) | Q12: =MAX(0,L12-N12-M12+O12) | R12: =MAX(0,P12-Q12) | S12: 45926 | T12: 45926 | U12: =IF(S12=T12,"一致","冲突") | V12: V3 | W12: V3 | X12: =IF(V12=W12,"一致","冲突") | Y12: =IF(OR(R12>0,U12="冲突",X12="冲突"),"高","低") | Z12: 团队模拟数据 | AA12: 依据业务规则生成，用于演示订单/BOM/库存/供应承诺闭环
A13: SO-2404-3-M-HOUSING | B13: EVT-0004 | C13: WO-20250925-004 | D13: SO-2404 | E13: 3 | F13: M-HOUSING | G13: 结构件 | H13: 45927 | I13: 1100 | J13: 2 | K13: 0 | L13: 1936 | M13: 176 | N13: 0 | O13: 440 | P13: =MAX(0,I13*J13-K13) | Q13: =MAX(0,L13-N13-M13+O13) | R13: =MAX(0,P13-Q13) | S13: 45926 | T13: 45926 | U13: =IF(S13=T13,"一致","冲突") | V13: V3 | W13: V3 | X13: =IF(V13=W13,"一致","冲突") | Y13: =IF(OR(R13>0,U13="冲突",X13="冲突"),"高","低") | Z13: 团队模拟数据 | AA13: 依据业务规则生成，用于演示订单/BOM/库存/供应承诺闭环
... A316: SO-2505-3-M-HOUSING | B316: EVT-0105 | C316: WO-20260403-105 | D316: SO-2505 | E316: 3 | F316: M-HOUSING | G316: 结构件 | H316: 46117 | I316: 1200 | J316: 2 | K316: 0 | L316: 2592 | M316: 192 | N316: 0 | O316: 0 | P316: =MAX(0,I316*J316-K316) | Q316: =MAX(0,L316-N316-M316+O316) | R316: =MAX(0,P316-Q316) | S316: 46116 | T316: 46116 | U316: =IF(S316=T316,"一致","冲突") | V316: V3 | W316: V3 | X316: =IF(V316=W316,"一致","冲突") | Y316: =IF(OR(R316>0,U316="冲突",X316="冲突"),"高","低") | Z316: 团队模拟数据 | AA316: 依据业务规则生成，用于演示订单/BOM/库存/供应承诺闭环

Sheet 05_数据质量测试
A1: DQRecordID | B1: ShiftID | C1: 日期 | D1: OEE | E1: 开动率 | F1: 性能率 | G1: 质量率 | H1: 计划生产时间_秒 | I1: 非计划停机_秒 | J1: 良品数 | K1: 总产量 | L1: 是否人工注错 | M1: ExpectedIssueType | N1: ExpectedSeverity | O1: AI_DetectedType_待填 | P1: AI_Explanation_待填 | Q1: 人工确认_待填 | R1: DetectionCorrect
A2: DQ-0001 | B2: SHIFT-PRE-20250922 | C2: 45922 | D2: 1.18 | E2: 0.8902 | F2: 0.9272 | G2: 0.9996 | H2: 17884 | I2: 668 | J2: 35800 | K2: 35815 | L2: 是 | M2: 数值越界 | N2: 高 | R2: =IF(O2="","待检测",IF(O2=M2,"正确","不一致"))
A3: DQ-0002 | B3: SHIFT-PRE-20250923 | C3: 45923 | D3: 0.5891 | E3: 0.6236 | F3: 0.9447 | G3: 0.9975 | H3: 29700 | I3: 10545 | J3: 26441 | K3: 26416 | L3: 是 | M3: 良品数大于总产量 | N3: 高 | R3: =IF(O3="","待检测",IF(O3=M3,"正确","不一致"))
A4: DQ-0003 | B4: SHIFT-PRE-20250924 | C4: 45924 | D4: 0.7498 | E4: 0.7833 | F4: 0.9572 | G4: 0.9951 | I4: 3006 | J4: 21490 | K4: 21594 | L4: 是 | M4: 关键字段缺失 | N4: 高 | R4: =IF(O4="","待检测",IF(O4=M4,"正确","不一致"))
A5: DQ-0004 | B5: SHIFT-PRE-20250925 | C5: 45925 | D5: 0.6546 | E5: 0.7179 | F5: 0.9118 | G5: 0.9933 | H5: 24300 | I5: -120 | J5: 16700 | K5: 16812 | L5: 是 | M5: 负停机时长 | N5: 高 | R5: =IF(O5="","待检测",IF(O5=M5,"正确","不一致"))
A6: DQ-0005 | B6: SHIFT-PRE-20250926 | C6: 45926 | D6: 0.8197 | E6: 0.8096 | F6: 0.926 | G6: 0.9867 | H6: 22920 | I6: 3364 | J6: 23000 | K6: 23310 | L6: 是 | M6: OEE分项不一致 | N6: 中 | R6: =IF(O6="","待检测",IF(O6=M6,"正确","不一致"))
A7: DQ-0006 | B7: SHIFT-PRE-20250926 | C7: 45929 | D7: 0.6467 | E7: 0.6717 | F7: 0.9628 | G7: 0.9967 | H7: 29132 | I7: 8847 | J7: 46000 | K7: 46150 | L7: 是 | M7: 复合主键重复 | N7: 中 | R7: =IF(O7="","待检测",IF(O7=M7,"正确","不一致"))
A8: DQ-0007 | B8: SHIFT-PRE-20250930 | C8: 45930 | D8: 0.4864 | E8: 0.5234 | F8: 0.9307 | G8: 0.9985 | H8: 26823 | I8: 11978 | J8: 16327 | K8: 16351 | L8: 否 | M8: 无异常 | N8: 低 | R8: =IF(O8="","待检测",IF(O8=M8,"正确","不一致"))
A9: DQ-0008 | B9: SHIFT-PRE-20251002 | C9: 45932 | D9: 0.7714 | E9: 0.8898 | F9: 0.8729 | G9: 0.9932 | H9: 27006 | I9: 2107 | J9: 22222 | K9: 22374 | L9: 否 | M9: 无异常 | N9: 低 | R9: =IF(O9="","待检测",IF(O9=M9,"正确","不一致"))
A10: DQ-0009 | B10: SHIFT-PRE-20251003 | C10: 45933 | D10: 0.3383 | E10: 0.3708 | F10: 0.9221 | G10: 0.9896 | H10: 27240 | I10: 15913 | J10: 19727 | K10: 19935 | L10: 否 | M10: 无异常 | N10: 低 | R10: =IF(O10="","待检测",IF(O10=M10,"正确","不一致"))
A11: DQ-0010 | B11: SHIFT-PRE-20251006 | C11: 45936 | D11: 0.7396 | E11: 0.7848 | F11: 0.9483 | G11: 0.9938 | H11: 28432 | I11: 5182 | J11: 54740 | K11: 55080 | L11: 否 | M11: 无异常 | N11: 低 | R11: =IF(O11="","待检测",IF(O11=M11,"正确","不一致"))
A12: DQ-0011 | B12: SHIFT-PRE-20251007 | C12: 45937 | D12: 1.18 | E12: 0.9238 | F12: 0.9819 | G12: 0.9925 | H12: 28252 | I12: 459 | J12: 31040 | K12: 31276 | L12: 是 | M12: 数值越界 | N12: 高 | R12: =IF(O12="","待检测",IF(O12=M12,"正确","不一致"))
A13: DQ-0012 | B13: SHIFT-PRE-20251008 | C13: 45938 | D13: 0.8304 | E13: 0.8908 | F13: 0.9354 | G13: 0.9966 | H13: 22678 | I13: 1246 | J13: 27892 | K13: 27867 | L13: 是 | M13: 良品数大于总产量 | N13: 高 | R13: =IF(O13="","待检测",IF(O13=M13,"正确","不一致"))
A14: DQ-0013 | B14: SHIFT-PRE-20251009 | C14: 45939 | D14: 0.4747 | E14: 0.6019 | F14: 0.8434 | G14: 0.9352 | I14: 6126 | J14: 13566 | K14: 14506 | L14: 是 | M14: 关键字段缺失 | N14: 高 | R14: =IF(O14="","待检测",IF(O14=M14,"正确","不一致"))
A15: DQ-0014 | B15: SHIFT-PRE-20251010 | C15: 45940 | D15: 0.7552 | E15: 0.8009 | F15: 0.9508 | G15: 0.9918 | H15: 27900 | I15: -120 | J15: 33336 | K15: 33612 | L15: 是 | M15: 负停机时长 | N15: 高 | R15: =IF(O15="","待检测",IF(O15=M15,"正确","不一致"))
A16: DQ-0015 | B16: SHIFT-PRE-20251013 | C16: 45943 | D16: 0.6544 | E16: 0.6293 | F16: 0.93 | G16: 0.9814 | H16: 29700 | I16: 8262 | J16: 45189 | K16: 46045 | L16: 是 | M16: OEE分项不一致 | N16: 中 | R16: =IF(O16="","待检测",IF(O16=M16,"正确","不一致"))
A17: DQ-0016 | B17: SHIFT-PRE-20251013 | C17: 45944 | D17: 0.379 | E17: 0.4139 | F17: 0.9157 | G17: 0.9958 | H17: 59400 | I17: 2526 | J17: 34600 | K17: 34745 | L17: 是 | M17: 复合主键重复 | N17: 中 | R17: =IF(O17="","待检测",IF(O17=M17,"正确","不一致"))
A18: DQ-0017 | B18: SHIFT-PRE-20251015 | C18: 45945 | D18: 0.1408 | E18: 0.1605 | F18: 0.8838 | G18: 0.9932 | H18: 55800 | I18: 17568 | J18: 13093 | K18: 13183 | L18: 否 | M18: 无异常 | N18: 低 | R18: =IF(O18="","待检测",IF(O18=M18,"正确","不一致"))
A19: DQ-0018 | B19: SHIFT-PRE-20251016 | C19: 45946 | D19: 0.3428 | E19: 0.3681 | F19: 0.9314 | G19: 0.9877 | H19: 56760 | I19: 5625 | J19: 20500 | K19: 20754 | L19: 否 | M19: 无异常 | N19: 低 | R19: =IF(O19="","待检测",IF(O19=M19,"正确","不一致"))
A20: DQ-0019 | B20: SHIFT-PRE-20251017 | C20: 45947 | D20: 0.3737 | E20: 0.3966 | F20: 0.9526 | G20: 0.9892 | H20: 53100 | I20: 3459 | J20: 31848 | K20: 32195 | L20: 否 | M20: 无异常 | N20: 低 | R20: =IF(O20="","待检测",IF(O20=M20,"正确","不一致"))
A21: DQ-0020 | B21: SHIFT-PRE-20251020 | C21: 45950 | D21: 0.4213 | E21: 0.4511 | F21: 0.941 | G21: 0.9927 | H21: 57621 | I21: 2647 | J21: 62154 | K21: 62609 | L21: 否 | M21: 无异常 | N21: 低 | R21: =IF(O21="","待检测",IF(O21=M21,"正确","不一致"))
A22: DQ-0021 | B22: SHIFT-PRE-20251021 | C22: 45951 | D22: 1.18 | E22: 0.387 | F22: 0.9377 | G22: 0.9959 | H22: 56882 | I22: 5156 | J22: 48430 | K22: 48631 | L22: 是 | M22: 数值越界 | N22: 高 | R22: =IF(O22="","待检测",IF(O22=M22,"正确","不一致"))
A23: DQ-0022 | B23: SHIFT-PRE-20251022 | C23: 45952 | D23: 0.2177 | E23: 0.2318 | F23: 0.9393 | G23: 0.9456 | H23: 54047 | I23: 11946 | J23: 12747 | K23: 12722 | L23: 是 | M23: 良品数大于总产量 | N23: 高 | R23: =IF(O23="","待检测",IF(O23=M23,"正确","不一致"))
A24: DQ-0023 | B24: SHIFT-PRE-20251023 | C24: 45953 | D24: 0.3732 | E24: 0.4094 | F24: 0.9115 | G24: 0.9955 | I24: 2700 | J24: 21850 | K24: 21948 | L24: 是 | M24: 关键字段缺失 | N24: 高 | R24: =IF(O24="","待检测",IF(O24=M24,"正确","不一致"))
A25: DQ-0024 | B25: SHIFT-PRE-20251024 | C25: 45954 | D25: 0.3052 | E25: 0.3586 | F25: 0.8667 | G25: 0.9822 | H25: 55020 | I25: -120 | J25: 21758 | K25: 22152 | L25: 是 | M25: 负停机时长 | N25: 高 | R25: =IF(O25="","待检测",IF(O25=M25,"正确","不一致"))
A26: DQ-0025 | B26: SHIFT-PRE-20251027 | C26: 45957 | D26: 0.5017 | E26: 0.4472 | F26: 0.943 | G26: 0.9919 | H26: 58380 | I26: 3307 | J26: 64020 | K26: 64540 | L26: 是 | M26: OEE分项不一致 | N26: 中 | R26: =IF(O26="","待检测",IF(O26=M26,"正确","不一致"))
A27: DQ-0026 | B27: SHIFT-PRE-20251027 | C27: 45959 | D27: 0.278 | E27: 0.312 | F27: 0.8911 | G27: 0.9831 | H27: 54589 | I27: 7356 | J27: 30200 | K27: 30717 | L27: 是 | M27: 复合主键重复 | N27: 中 | R27: =IF(O27="","待检测",IF(O27=M27,"正确","不一致"))
A28: DQ-0027 | B28: SHIFT-PRE-20251030 | C28: 45960 | D28: 0.3799 | E28: 0.4153 | F28: 0.9252 | G28: 0.9886 | H28: 55800 | I28: 3179 | J28: 22610 | K28: 22870 | L28: 否 | M28: 无异常 | N28: 低 | R28: =IF(O28="","待检测",IF(O28=M28,"正确","不一致"))
A29: DQ-0028 | B29: SHIFT-PRE-20251031 | C29: 45961 | D29: 0.4838 | E29: 0.5509 | F29: 0.9176 | G29: 0.9569 | H29: 38269 | I29: 2995 | J29: 17102 | K29: 17872 | L29: 否 | M29: 无异常 | N29: 低 | R29: =IF(O29="","待检测",IF(O29=M29,"正确","不一致"))
A30: DQ-0029 | B30: SHIFT-PRE-20251103 | C30: 45964 | D30: 0.8187 | E30: 0.8913 | F30: 0.9411 | G30: 0.9761 | H30: 28235 | I30: 2245 | J30: 58985 | K30: 60430 | L30: 否 | M30: 无异常 | N30: 低 | R30: =IF(O30="","待检测",IF(O30=M30,"正确","不一致"))
A31: DQ-0030 | B31: SHIFT-PRE-20251104 | C31: 45965 | D31: 0.6196 | E31: 0.6821 | F31: 0.9386 | G31: 0.9677 | H31: 27829 | I31: 6914 | J31: 44230 | K31: 45705 | L31: 否 | M31: 无异常 | N31: 低 | R31: =IF(O31="","待检测",IF(O31=M31,"正确","不一致"))
A32: DQ-0031 | B32: SHIFT-PRE-20251105 | C32: 45966 | D32: 1.18 | E32: 0.8281 | F32: 0.937 | G32: 0.985 | H32: 20984 | I32: 2842 | J32: 25316 | K32: 25701 | L32: 是 | M32: 数值越界 | N32: 高 | R32: =IF(O32="","待检测",IF(O32=M32,"正确","不一致"))
A33: DQ-0032 | B33: SHIFT-PRE-20251106 | C33: 45967 | D33: 0.7305 | E33: 0.7809 | F33: 0.9385 | G33: 0.9968 | H33: 24874 | I33: 3723 | J33: 19469 | K33: 19444 | L33: 是 | M33: 良品数大于总产量 | N33: 高 | R33: =IF(O33="","待检测",IF(O33=M33,"正确","不一致"))
A34: DQ-0033 | B34: SHIFT-PRE-20251107 | C34: 45968 | D34: 0.4629 | E34: 0.5603 | F34: 0.8697 | G34: 0.95 | I34: 8388 | J34: 18552 | K34: 19528 | L34: 是 | M34: 关键字段缺失 | N34: 高 | R34: =IF(O34="","待检测",IF(O34=M34,"正确","不一致"))
A35: DQ-0034 | B35: SHIFT-PRE-20251110 | C35: 45971 | D35: 0.7055 | E35: 0.7574 | F35: 0.9494 | G35: 0.9811 | H35: 27760 | I35: -120 | J35: 49800 | K35: 50760 | L35: 是 | M35: 负停机时长 | N35: 高 | R35: =IF(O35="","待检测",IF(O35=M35,"正确","不一致"))
A36: DQ-0035 | B36: SHIFT-PRE-20251111 | C36: 45972 | D36: 0.6166 | E36: 0.574 | F36: 0.9669 | G36: 0.967 | H36: 29040 | I36: 12372 | J36: 41555 | K36: 42975 | L36: 是 | M36: OEE分项不一致 | N36: 中 | R36: =IF(O36="","待检测",IF(O36=M36,"正确","不一致"))
A37: DQ-0036 | B37: SHIFT-PRE-20251111 | C37: 45973 | D37: 0.5271 | E37: 0.5791 | F37: 0.9388 | G37: 0.9696 | H37: 25632 | I37: 9424 | J37: 28421 | K37: 29311 | L37: 是 | M37: 复合主键重复 | N37: 中 | R37: =IF(O37="","待检测",IF(O37=M37,"正确","不一致"))
A38: DQ-0037 | B38: SHIFT-PRE-20251113 | C38: 45974 | D38: 0.5792 | E38: 0.6383 | F38: 0.9298 | G38: 0.976 | H38: 27900 | I38: 8956 | J38: 17238 | K38: 17662 | L38: 否 | M38: 无异常 | N38: 低 | R38: =IF(O38="","待检测",IF(O38=M38,"正确","不一致"))
A39: DQ-0038 | B39: SHIFT-PRE-20251114 | C39: 45975 | D39: 0.6113 | E39: 0.6865 | F39: 0.9057 | G39: 0.983 | H39: 26441 | I39: 7437 | J39: 19117 | K39: 19447 | L39: 否 | M39: 无异常 | N39: 低 | R39: =IF(O39="","待检测",IF(O39=M39,"正确","不一致"))
A40: DQ-0039 | B40: SHIFT-PRE-20251117 | C40: 45978 | D40: 0.613 | E40: 0.6729 | F40: 0.9214 | G40: 0.9887 | H40: 28777 | I40: 8575 | J40: 42870 | K40: 43360 | L40: 否 | M40: 无异常 | N40: 低 | R40: =IF(O40="","待检测",IF(O40=M40,"正确","不一致"))
...

Sheet 06_岗位画像_模拟
A1: RoleID | B1: 演示用户 | C1: 岗位名称 | D1: 组织范围 | E1: 产线范围 | F1: 必看指标 | G1: 数据颗粒度 | H1: 推送偏好 | I1: 数据性质
A2: ROLE-CEO | B2: 演示用户-经营层 | C2: 经营层 | D2: 全集团 | E2: 全部产线 | F2: OEE、重大交付风险、跨部门处置进度 | G2: 仅汇总 | H2: 即时高风险+每日摘要 | I2: 团队模拟数据
A3: ROLE-PLANT | B3: 演示用户-厂长 | C3: 厂长 | D3: 示范工厂 | E3: 全部产线 | F3: 产线OEE、停机损失、良率 | G3: 产线/班次 | H3: 即时高风险+每班摘要 | I3: 团队模拟数据
A4: ROLE-PROD | B4: 演示用户-生产主管 | C4: 生产主管 | D4: 示范工厂 | E4: LINE-R01 | F4: 产量、性能损失、工单进度 | G4: 班次/工单 | H4: 事件触发 | I4: 团队模拟数据
A5: ROLE-EQUIP | B5: 演示用户-设备工程师 | C5: 设备工程师 | D5: 示范工厂 | E5: LINE-R01 | F5: 非计划停机、设备位置、维修任务 | G5: 停机事件 | H5: 事件触发 | I5: 团队模拟数据
A6: ROLE-QA | B6: 演示用户-质量工程师 | C6: 质量工程师 | D6: 示范工厂 | E6: LINE-R01 | F6: 质量率、良品数、冻结量、异常批次 | G6: 批次/物料 | H6: 事件触发 | I6: 团队模拟数据
A7: ROLE-SC | B7: 演示用户-供应链 | C7: 供应链负责人 | D7: 示范工厂 | E7: 全部产线 | F7: 物料缺口、库存、供应承诺 | G7: 物料明细 | H7: 事件触发 | I7: 团队模拟数据

Sheet 07_推送规则_模拟
A1: RuleID | B1: 触发条件 | C1: 严重度 | D1: 接收岗位 | E1: 推送方式 | F1: 消息内容颗粒度 | G1: 去重窗口_分钟 | H1: 升级策略 | I1: 状态 | J1: 数据性质
A2: PUSH-001 | B2: OEE低于75% | C2: 高 | D2: 厂长 | E2: 飞书消息卡片 | F2: 产线、班次、OEE及三项损失 | G2: 120 | H2: 30分钟未确认升级经营层 | I2: 启用 | J2: 团队模拟数据
A3: PUSH-002 | B3: 非计划停机超过60分钟 | C3: 高 | D3: 设备工程师 | E3: 飞书消息卡片+任务 | F3: 设备位置、停机原因、持续时间 | G3: 60 | H3: 20分钟未响应升级厂长 | I3: 启用 | J3: 团队模拟数据
A4: PUSH-003 | B4: 质量率低于98% | C4: 高 | D4: 质量工程师 | E4: 飞书消息卡片+任务 | F4: 总产量、良品数、缺陷数量 | G4: 120 | H4: 30分钟未确认升级质量负责人 | I4: 启用 | J4: 团队模拟数据
A5: PUSH-004 | B5: 性能率低于85% | C5: 中 | D5: 生产主管 | E5: 飞书消息卡片 | F5: 计划产量、实际产量、速度损失 | G5: 240 | H5: 每班汇总 | I5: 启用 | J5: 团队模拟数据
A6: PUSH-005 | B6: 物料缺口大于0 | C6: 高 | D6: 供应链负责人 | E6: 飞书消息卡片+任务 | F6: 订单、物料、需求日、缺口量 | G6: 120 | H6: 30分钟未确认升级厂长 | I6: 启用 | J6: 团队模拟数据
A7: PUSH-006 | B7: ERP与SRM日期冲突 | C7: 中 | D7: 供应链负责人 | E7: 飞书消息卡片 | F7: 两个来源日期及影响订单 | G7: 240 | H7: 每日汇总 | I7: 启用 | J7: 团队模拟数据
A8: PUSH-007 | B8: BOM版本冲突 | C8: 高 | D8: 研发工程师 | E8: 飞书消息卡片+任务 | F8: 订单BOM、工单BOM、物料 | G8: 120 | H8: 30分钟未确认升级研发负责人 | I8: 启用 | J8: 团队模拟数据
A9: PUSH-008 | B9: 数据质量高风险 | C9: 高 | D9: 字段责任人 | E9: 飞书消息卡片 | F9: 原始值、规则、待确认问题 | G9: 120 | H9: 30分钟未确认升级数据负责人 | I9: 启用 | J9: 团队模拟数据

Sheet 08_处置任务_模拟
A1: TaskID | B1: EventID | C1: WorkOrderID | D1: 任务措施 | E1: 责任岗位 | F1: 截止日期 | G1: 状态 | H1: 处理结果_待填 | I1: 数据性质
A2: TASK-0001 | B2: EVT-0002 | C2: WO-20250923-002 | D2: 检查非计划停机原因并反馈预计恢复时间 | E2: 设备工程师 | F2: 45924 | G2: 处理中 | I2: 团队模拟数据
A3: TASK-0002 | B3: EVT-0002 | C3: WO-20250923-002 | D3: 核对良率异常及冻结批次 | E3: 质量工程师 | F3: 45924 | G3: 待处理 | I3: 团队模拟数据
A4: TASK-0003 | B4: EVT-0002 | C4: WO-20250923-002 | D4: 核对物料缺口和供应承诺 | E4: 供应链负责人 | F4: 45924 | G4: 待处理 | I4: 团队模拟数据
A5: TASK-0004 | B5: EVT-0003 | C5: WO-20250924-003 | D5: 检查非计划停机原因并反馈预计恢复时间 | E5: 设备工程师 | F5: 45925 | G5: 处理中 | I5: 团队模拟数据
A6: TASK-0005 | B6: EVT-0003 | C6: WO-20250924-003 | D6: 核对良率异常及冻结批次 | E6: 质量工程师 | F6: 45925 | G6: 待处理 | I6: 团队模拟数据
A7: TASK-0006 | B7: EVT-0003 | C7: WO-20250924-003 | D7: 核对物料缺口和供应承诺 | E7: 供应链负责人 | F7: 45925 | G7: 待处理 | I7: 团队模拟数据
A8: TASK-0007 | B8: EVT-0004 | C8: WO-20250925-004 | D8: 检查非计划停机原因并反馈预计恢复时间 | E8: 设备工程师 | F8: 45926 | G8: 处理中 | I8: 团队模拟数据
A9: TASK-0008 | B9: EVT-0004 | C9: WO-20250925-004 | D9: 核对良率异常及冻结批次 | E9: 质量工程师 | F9: 45926 | G9: 待处理 | I9: 团队模拟数据
A10: TASK-0009 | B10: EVT-0004 | C10: WO-20250925-004 | D10: 核对物料缺口和供应承诺 | E10: 供应链负责人 | F10: 45926 | G10: 待处理 | I10: 团队模拟数据
A11: TASK-0010 | B11: EVT-0005 | C11: WO-20250926-005 | D11: 检查非计划停机原因并反馈预计恢复时间 | E11: 设备工程师 | F11: 45927 | G11: 处理中 | I11: 团队模拟数据
A12: TASK-0011 | B12: EVT-0005 | C12: WO-20250926-005 | D12: 核对良率异常及冻结批次 | E12: 质量工程师 | F12: 45927 | G12: 待处理 | I12: 团队模拟数据
A13: TASK-0012 | B13: EVT-0005 | C13: WO-20250926-005 | D13: 核对物料缺口和供应承诺 | E13: 供应链负责人 | F13: 45927 | G13: 待处理 | I13: 团队模拟数据
... A76: TASK-0075 | B76: EVT-0030 | C76: WO-20251104-030 | D76: 核对物料缺口和供应承诺 | E76: 供应链负责人 | F76: 45966 | G76: 待处理 | I76: 团队模拟数据

Sheet 09_字段字典
A1: 工作表 | B1: 字段 | C1: 建议飞书字段类型 | D1: 定义/计算口径 | E1: 数据性质
A2: 01_OEE班次 | B2: ShiftID | C2: 文本 | D2: 阶段+日期生成的班次唯一键 | E2: 公开数据派生键
A3: 01_OEE班次 | B3: OEE原值 | C3: 百分比 | D3: 来源数据集的OEE | E3: 公开真实数据
A4: 01_OEE班次 | B4: OEE复算 | C4: 公式 | D4: 开动率×性能率×质量率 | E4: 工作簿公式
A5: 01_OEE班次 | B5: 良率复算 | C5: 公式 | D5: 良品数÷总产量 | E5: 工作簿公式
A6: 02_停机明细 | B6: StopEventID | C6: 文本 | D6: 停机事件唯一键 | E6: 公开数据派生键
A7: 02_停机明细 | B7: ShiftID | C7: 文本 | D7: 关联OEE班次表 | E7: 公开数据派生键
A8: 03_工单映射_模拟 | B8: WorkOrderID | C8: 文本 | D8: 演示工单唯一键 | E8: 团队模拟
A9: 04_订单物料_模拟 | B9: BusinessKey | C9: 文本 | D9: 订单号+订单行+物料编码 | E9: 团队模拟
A10: 04_订单物料_模拟 | B10: EventID | C10: 文本 | D10: 贯穿问题、任务和复盘的事件编号 | E10: 团队模拟
A11: 04_订单物料_模拟 | B11: 物料缺口 | C11: 公式 | D11: max(0,需求量-需求日前可用量) | E11: 工作簿公式
A12: 05_数据质量测试 | B12: ExpectedIssueType | C12: 单选 | D12: 人工注错的标准答案 | E12: 实验标签
... A16: 07_推送规则_模拟 | B16: 去重窗口_分钟 | C16: 数字 | D16: 相同事件在窗口期内不重复推送 | E16: 团队模拟
A18: --- v3 新增字段字典 ---
A19: 表名 | B19: 字段名 | C19: 类型 | D19: 说明
A20: 16_不良类型_模拟 | B20: DefectDetailID | C20: 文本 | D20: 不良明细记录唯一ID (DEF-00001~DEF-01575)
A21: 16_不良类型_模拟 | B21: SimShiftID | C21: 关联 | D21: 关联12_多产线班次_模拟
A22: 16_不良类型_模拟 | B22: 不良类型 | C22: 单选 | D22: 外观不良/尺寸超差/功能失效/电气不良/其他不良
A23: 16_不良类型_模拟 | B23: 不良数量 | C23: 数字 | D23: 该班次该不良类型的数量(整数)
A24: 16_不良类型_模拟 | B24: 不良占比 | C24: 数字 | D24: 该类型占班次不良总数的比例(0~1, 显示0.00%)
A25: 17_质量冻结明细_模拟 | B25: FreezeID | C25: 文本 | D25: 冻结记录唯一ID (FZ-0001~FZ-0045)
A26: 17_质量冻结明细_模拟 | B26: BusinessKey | C26: 关联 | D26: 关联04_订单物料_模拟
A27: 17_质量冻结明细_模拟 | B27: 冻结原因 | C27: 单选 | D27: 抽检不合格/功能测试失败/来料质量异常/电气性能异常/工艺参数偏移/尺寸超差/外观不良
A28: 17_质量冻结明细_模拟 | B28: 关联不良类型 | C28: 单选 | D28: 关联16表的不良类型分类
A29: 17_质量冻结明细_模拟 | B29: 风险等级 | C29: 公式 | D29: VLOOKUP 04表风险等级
A30: 17_质量冻结明细_模拟 | B30: 需要人工确认 | C30: 公式 | D30: 风险等级=高且状态≠已解除→是
... A41: 13_多产线停机(新增) | B41: 同02表 | C41: 公式 | D41: 字段相同，公式引用18表

Sheet 10_多产线说明
A1: BIFROST 多产线模拟扩展层｜使用说明
A3: 结论 | B3: 原始公开数据只有一条真实产线；LINE-R01仅代表来源线。LINE-S01/S02/S03全部是团队模拟场景。
A4: 使用目的 | B4: 用于展示多产线横向对比、智能体分工、主动推送和管理员公式配置能力。
A5: 禁止表述 | B5: 不得称为合作企业真实多产线数据，不得用模拟层证明企业实际经营改善。
A6: 推荐页面 | B6: 真实单线深度分析｜模拟多产线管理演示；两个入口必须显示数据性质标签。
A7: 真实来源 | B7: https://zenodo.org/records/17855209
A8: 模拟版本 | B8: SIM-v2.2-20260807-20260804
A9: 记录规模 | B9: 315条模拟班次；3525条模拟停机事件；909条规则告警
A11: 工作表 | B11: 用途 | C11: 主键 | D11: 来源关联 | E11: 数据性质 | F11: 飞书建议 | G11: 关键限制 | H11: 更新方式
A12: 01_OEE班次 | B12: 真实单线OEE | C12: ShiftID | D12: - | E12: 公开真实 | F12: 真实分析入口 | G12: 无LineID | H12: 保留原表
A13: 11_产线主数据_模拟 | B13: 模拟参数 | C13: LineID | D13: - | E13: 团队模拟 | F13: 配置表 | G13: 参数可调整 | H13: 管理员发布版本
A14: 12_多产线班次_模拟 | B14: 横向OEE | C14: SimShiftID | D14: SourceShiftID | E14: 团队模拟 | F14: 多线看板 | G14: 不能冒充真实线 | H14: 按版本重算
A15: 13_多产线停机_模拟 | B15: 停机追溯 | C15: SimStopEventID | D15: SourceStopEventID | E15: 团队模拟 | F15: 根因/Pareto | G15: 工位为演示映射 | H15: 按版本重算
A16: 14_多产线告警_模拟 | B16: 智能体路由 | C16: EventID | D16: SimShiftID | E16: 团队模拟 | F16: 预警与任务 | G16: 高风险需人工确认 | H16: 由规则重算
A17: 15_多产线校验 | B17: 质量核对 | C17: LineID+阶段 | D17: 12/14表 | E17: 计算汇总 | F17: 管理员验收 | G17: 用于核数 | H17: 公式自动更新
A19: --- v3 5M1E 第一阶段补充说明 ---
A20: 16_不良类型_模拟：基于12表315个SimShiftID生成，每班次5种不良类型，共1575行
A21: 三条线不良画像差异：S01均衡、S02功能失效+电气主导、S03外观+尺寸主导
A22: 17_质量冻结明细_模拟：45行，与04表冻结记录1:1对齐，冻结总量6000
A23: 18_换产标准_模拟：3条规则，02/13表通过VLOOKUP引用实现公式驱动
A24: 所有新增数据为团队模拟数据(SIM-v2.2-20260807-20260805)，不得解释为合作企业真实数据

Sheet 11_产线主数据_模拟
A1: LineID | B1: 产线名称 | C1: 场景画像 | D1: 演示产品族 | E1: 目标OEE | F1: 产能系数 | G1: 改善前_开动率偏移 | H1: 改善后_开动率偏移 | I1: 改善前_性能率偏移 | J1: 改善后_性能率偏移 | K1: 改善前_质量率偏移 | L1: 改善后_质量率偏移 | M1: 改善前_非计划停机系数 | N1: 改善后_非计划停机系数 | O1: 主要风险 | P1: 默认智能体 | Q1: 数据性质 | R1: 模拟版本
A2: LINE-S01 | B2: 稳态基准线 | C2: 稳定生产、波动较小，作为横向比较基准 | D2: 智能终端系列 | E2: 0.78 | F2: 1 | G2: 0.02 | H2: 0.025 | I2: 0.01 | J2: 0.015 | K2: 0 | L2: 0.001 | M2: 0.9 | N2: 0.82 | O2: 综合效率波动 | P2: 生产诊断智能体 | Q2: 团队模拟数据（基于公开单线数据派生） | R2: SIM-v2.2-20260807-20260804
A3: LINE-S02 | B3: 设备瓶颈线 | C3: 关键设备停机偏多，改善后故障影响逐步收敛 | D3: 视觉设备系列 | E3: 0.74 | F3: 0.95 | G3: -0.06 | H3: -0.025 | I3: -0.005 | J3: 0.005 | K3: 0.001 | L3: 0.002 | M3: 1.35 | N3: 1.1 | O3: 设备非计划停机 | P3: 设备诊断智能体 | Q3: 团队模拟数据（基于公开单线数据派生） | R3: SIM-v2.2-20260807-20260804
A4: LINE-S03 | B4: 质量波动线 | C4: 产能较高但质量与节拍波动，改善后质量损失下降 | D4: 音频模组系列 | E4: 0.76 | F4: 1.08 | G4: 0.005 | H4: 0.015 | I4: -0.025 | J4: -0.01 | K4: -0.025 | L4: -0.01 | M4: 0.98 | N4: 0.9 | O4: 质量与节拍波动 | P4: 质量分析智能体 | Q4: 团队模拟数据（基于公开单线数据派生） | R4: SIM-v2.2-20260807-20260804

Sheet 12_多产线班次_模拟
A1: SimShiftID | B1: SourceShiftID | C1: LineID | D1: 产线名称 | E1: 场景画像 | F1: 阶段 | G1: 班次日期 | H1: 演示产品族 | I1: 计划生产时间_秒 | J1: 开动率 | K1: 性能率 | L1: 质量率 | M1: OEE复算 | N1: 总产量 | O1: 良品数 | P1: 良率复算 | Q1: 计划停机_秒 | R1: 非计划停机_秒 | S1: 全速生产_秒 | T1: 低速生产_秒 | U1: 目标OEE | V1: OEE偏差 | W1: 风险等级 | X1: 数据性质 | Y1: 来源链接 | Z1: 模拟版本 | AA1: 生成规则摘要
A2: LINE-S01-PRE-20250922 | B2: SHIFT-PRE-20250922 | C2: LINE-S01 | D2: 稳态基准线 | E2: 稳定生产、波动较小，作为横向比较基准 | F2: 改善前 | G2: 45922 | H2: 智能终端系列 | I2: 17884 | J2: 0.8982 | K2: 0.925533 | L2: 0.997378 | M2: =J2*K2*L2 | N2: 36511 | O2: =ROUND(N2*L2,0) | P2: =IF(N2=0,0,O2/N2) | Q2: 12849 | R2: 600 | S2: 14604 | T2: 1212 | U2: 0.78 | V2: =M2-U2 | W2: =IF(OR(J2<0.65,L2<0.96,M2<0.6),"高",IF(OR(J2<0.78,K2<0.88,L2<0.98,M2<0.75),"中","低")) | X2: 团队模拟数据（基于公开单线数据派生） | Y2: https://zenodo.org/records/17855209 | Z2: SIM-v2.2-20260807-20260804 | AA2: 基于SHIFT-PRE-20250922；应用稳态基准线的改善前参数、确定性周期扰动及停机事件缩放
A3: LINE-S02-PRE-20250922 | B3: SHIFT-PRE-20250922 | C3: LINE-S02 | D3: 设备瓶颈线 | E3: 关键设备停机偏多，改善后故障影响逐步收敛 | F3: 改善前 | G3: 45922 | H3: 视觉设备系列 | I3: 17884 | J3: 0.832867 | K3: 0.928867 | L3: 0.9995 | M3: =J3*K3*L3 | N3: 33627 | O3: =ROUND(N3*L3,0) | P3: =IF(N3=0,0,O3/N3) | Q3: 13373 | R3: 990 | S3: 13627 | T3: 1383 | U3: 0.74 | V3: =M3-U3 | W3: =IF(OR(J3<0.65,L3<0.96,M3<0.6),"高",IF(OR(J3<0.78,K3<0.88,L3<0.98,M3<0.75),"中","低")) | X3: 团队模拟数据（基于公开单线数据派生） | Y3: https://zenodo.org/records/17855209 | Z3: SIM-v2.2-20260807-20260804 | AA3: 基于SHIFT-PRE-20250922；应用设备瓶颈线的改善前参数、确定性周期扰动及停机事件缩放
A4: LINE-S03-PRE-20250922 | B4: SHIFT-PRE-20250922 | C4: LINE-S03 | D4: 质量波动线 | E4: 产能较高但质量与节拍波动，改善后质量损失下降 | F4: 改善前 | G4: 45922 | H4: 音频模组系列 | I4: 17884 | J4: 0.8872 | K4: 0.895533 | L4: 0.973711 | M4: =J4*K4*L4 | N4: 39884 | O4: =ROUND(N4*L4,0) | P4: =IF(N4=0,0,O4/N4) | Q4: 13111 | R4: 738 | S4: 15877 | T4: 1580 | U4: 0.76 | V4: =M4-U4 | W4: =IF(OR(J4<0.65,L4<0.96,M4<0.6),"高",IF(OR(J4<0.78,K4<0.88,L4<0.98,M4<0.75),"中","低")) | X4: 团队模拟数据（基于公开单线数据派生） | Y4: https://zenodo.org/records/17855209 | Z4: SIM-v2.2-20260807-20260804 | AA4: 基于SHIFT-PRE-20250922；应用质量波动线的改善前参数、确定性周期扰动及停机事件缩放
A5: LINE-S01-PRE-20250923 | B5: SHIFT-PRE-20250923 | C5: LINE-S01 | D5: 稳态基准线 | E5: 稳定生产、波动较小，作为横向比较基准 | F5: 改善前 | G5: 45923 | H5: 智能终端系列 | I5: 29700 | J5: 0.640933 | K5: 0.9547 | L5: 0.998389 | M5: =J5*K5*L5 | N5: 25697 | O5: =ROUND(N5*L5,0) | P5: =IF(N5=0,0,O5/N5) | Q5: 621 | R5: 9450 | S5: 17669 | T5: 1033 | U5: 0.78 | V5: =M5-U5 | W5: =IF(OR(J5<0.65,L5<0.96,M5<0.6),"高",IF(OR(J5<0.78,K5<0.88,L5<0.98,M5<0.75),"中","低")) | X5: 团队模拟数据（基于公开单线数据派生） | Y5: https://zenodo.org/records/17855209 | Z5: SIM-v2.2-20260807-20260804 | AA5: 基于SHIFT-PRE-20250923；应用稳态基准线的改善前参数、确定性周期扰动及停机事件缩放
A6: LINE-S02-PRE-20250923 | B6: SHIFT-PRE-20250923 | C6: LINE-S02 | D6: 设备瓶颈线 | E6: 关键设备停机偏多，改善后故障影响逐步收敛 | F6: 改善前 | G6: 45923 | H6: 视觉设备系列 | I6: 29700 | J6: 0.5756 | K6: 0.926367 | L6: 0.995833 | M6: =J6*K6*L6 | N6: 25486 | O6: =ROUND(N6*L6,0) | P6: =IF(N6=0,0,O6/N6) | Q6: 647 | R6: 14586 | S6: 16491 | T6: 1179 | U6: 0.74 | V6: =M6-U6 | W6: =IF(OR(J6<0.65,L6<0.96,M6<0.6),"高",IF(OR(J6<0.78,K6<0.88,L6<0.98,M6<0.75),"中","低")) | X6: 团队模拟数据（基于公开单线数据派生） | Y6: https://zenodo.org/records/17855209 | Z6: SIM-v2.2-20260807-20260804 | AA6: 基于SHIFT-PRE-20250923；应用设备瓶颈线的改善前参数、确定性周期扰动及停机事件缩放
A7: LINE-S03-PRE-20250923 | B7: SHIFT-PRE-20250923 | C7: LINE-S03 | D7: 质量波动线 | E7: 产能较高但质量与节拍波动，改善后质量损失下降 | F7: 改善前 | G7: 45923 | H7: 音频模组系列 | I7: 29700 | J7: 0.629933 | K7: 0.9247 | L7: 0.974722 | M7: =J7*K7*L7 | N7: 28085 | O7: =ROUND(N7*L7,0) | P7: =IF(N7=0,0,O7/N7) | Q7: 634 | R7: 11484 | S7: 18414 | T7: 1348 | U7: 0.76 | V7: =M7-U7 | W7: =IF(OR(J7<0.65,L7<0.96,M7<0.6),"高",IF(OR(J7<0.78,K7<0.88,L7<0.98,M7<0.75),"中","低")) | X7: 团队模拟数据（基于公开单线数据派生） | Y7: https://zenodo.org/records/17855209 | Z7: SIM-v2.2-20260807-20260804 | AA7: 基于SHIFT-PRE-20250923；应用质量波动线的改善前参数、确定性周期扰动及停机事件缩放
A8: LINE-S01-PRE-20250924 | B8: SHIFT-PRE-20250924 | C8: LINE-S01 | D8: 稳态基准线 | E8: 稳定生产、波动较小，作为横向比较基准 | F8: 改善前 | G8: 45924 | H8: 智能终端系列 | I8: 28800 | J8: 0.809967 | K8: 0.978867 | L8: 0.9991 | M8: =J8*K8*L8 | N8: 21594 | O8: =ROUND(N8*L8,0) | P8: =IF(N8=0,0,O8/N8) | Q8: 3169 | R8: 2646 | S8: 20802 | T8: 1402 | U8: 0.78 | V8: =M8-U8 | W8: =IF(OR(J8<0.65,L8<0.96,M8<0.6),"高",IF(OR(J8<0.78,K8<0.88,L8<0.98,M8<0.75),"中","低")) | X8: 团队模拟数据（基于公开单线数据派生） | Y8: https://zenodo.org/records/17855209 | Z8: SIM-v2.2-20260807-20260804 | AA8: 基于SHIFT-PRE-20250924；应用稳态基准线的改善前参数、确定性周期扰动及停机事件缩放
A9: LINE-S02-PRE-20250924 | B9: SHIFT-PRE-20250924 | C9: LINE-S02 | D9: 设备瓶颈线 | E9: 关键设备停机偏多，改善后故障影响逐步收敛 | F9: 改善前 | G9: 45924 | H9: 视觉设备系列 | I9: 28800 | J9: 0.7193 | K9: 0.950533 | L9: 0.996544 | M9: =J9*K9*L9 | N9: 19876 | O9: =ROUND(N9*L9,0) | P9: =IF(N9=0,0,O9/N9) | Q9: 3299 | R9: 4386 | S9: 20251 | T9: 1600 | U9: 0.74 | V9: =M9-U9 | W9: =IF(OR(J9<0.65,L9<0.96,M9<0.6),"高",IF(OR(J9<0.78,K9<0.88,L9<0.98,M9<0.75),"中","低")) | X9: 团队模拟数据（基于公开单线数据派生） | Y9: https://zenodo.org/records/17855209 | Z9: SIM-v2.2-20260807-20260804 | AA9: 基于SHIFT-PRE-20250924；应用设备瓶颈线的改善前参数、确定性周期扰动及停机事件缩放
A10: LINE-S03-PRE-20250924 | B10: SHIFT-PRE-20250924 | C10: LINE-S03 | D10: 质量波动线 | E10: 产能较高但质量与节拍波动，改善后质量损失下降 | F10: 改善前 | G10: 45924 | H10: 音频模组系列 | I10: 28800 | J10: 0.798967 | K10: 0.9172 | L10: 0.966989 | M10: =J10*K10*L10 | N10: 23594 | O10: =ROUND(N10*L10,0) | P10: =IF(N10=0,0,O10/N10) | Q10: 3234 | R10: 3168 | S10: 22618 | T10: 1829 | U10: 0.76 | V10: =M10-U10 | W10: =IF(OR(J10<0.65,L10<0.96,M10<0.6),"高",IF(OR(J10<0.78,K10<0.88,L10<0.98,M10<0.75),"中","低")) | X10: 团队模拟数据（基于公开单线数据派生） | Y10: https://zenodo.org/records/17855209 | Z10: SIM-v2.2-20260807-20260804 | AA10: 基于SHIFT-PRE-20250924；应用质量波动线的改善前参数、确定性周期扰动及停机事件缩放
A11: LINE-S01-PRE-20250925 | B11: SHIFT-PRE-20250925 | C11: LINE-S01 | D11: 稳态基准线 | E11: 稳定生产、波动较小，作为横向比较基准 | F11: 改善前 | G11: 45925 | H11: 智能终端系列 | I11: 24300 | J11: 0.728567 | K11: 0.913467 | L11: 0.991967 | M11: =J11*K11*L11 | N11: 17270 | O11: =ROUND(N11*L11,0) | P11: =IF(N11=0,0,O11/N11) | Q11: 7559 | R11: 3894 | S11: 16006 | T11: 1390 | U11: 0.78 | V11: =M11-U11 | W11: =IF(OR(J11<0.65,L11<0.96,M11<0.6),"高",IF(OR(J11<0.78,K11<0.88,L11<0.98,M11<0.75),"中","低")) | X11: 团队模拟数据（基于公开单线数据派生） | Y11: https://zenodo.org/records/17855209 | Z11: SIM-v2.2-20260807-20260804 | AA11: 基于SHIFT-PRE-20250925；应用稳态基准线的改善前参数、确定性周期扰动及停机事件缩放
A12: LINE-S02-PRE-20250925 | B12: SHIFT-PRE-20250925 | C12: LINE-S02 | D12: 设备瓶颈线 | E12: 关键设备停机偏多，改善后故障影响逐步收敛 | F12: 改善前 | G12: 45925 | H12: 视觉设备系列 | I12: 24300 | J12: 0.663233 | K12: 0.9168 | L12: 0.997856 | M12: =J12*K12*L12 | N12: 15909 | O12: =ROUND(N12*L12,0) | P12: =IF(N12=0,0,O12/N12) | Q12: 7867 | R12: 6228 | S12: 14936 | T12: 1587 | U12: 0.74 | V12: =M12-U12 | W12: =IF(OR(J12<0.65,L12<0.96,M12<0.6),"高",IF(OR(J12<0.78,K12<0.88,L12<0.98,M12<0.75),"中","低")) | X12: 团队模拟数据（基于公开单线数据派生） | Y12: https://zenodo.org/records/17855209 | Z12: SIM-v2.2-20260807-20260804 | AA12: 基于SHIFT-PRE-20250925；应用设备瓶颈线的改善前参数、确定性周期扰动及停机事件缩放
A13: LINE-S03-PRE-20250925 | B13: SHIFT-PRE-20250925 | C13: LINE-S03 | D13: 质量波动线 | E13: 产能较高但质量与节拍波动，改善后质量损失下降 | F13: 改善前 | G13: 45925 | H13: 音频模组系列 | I13: 24300 | J13: 0.717567 | K13: 0.883467 | L13: 0.9683 | M13: =J13*K13*L13 | N13: 17521 | O13: =ROUND(N13*L13,0) | P13: =IF(N13=0,0,O13/N13) | Q13: 7713 | R13: 5022 | S13: 17401 | T13: 1813 | U13: 0.76 | V13: =M13-U13 | W13: =IF(OR(J13<0.65,L13<0.96,M13<0.6),"高",IF(OR(J13<0.78,K13<0.88,L13<0.98,M13<0.75),"中","低")) | X13: 团队模拟数据（基于公开单线数据派生） | Y13: https://zenodo.org/records/17855209 | Z13: SIM-v2.2-20260807-20260804 | AA13: 基于SHIFT-PRE-20250925；应用质量波动线的改善前参数、确定性周期扰动及停机事件缩放
... A316: LINE-S03-POST-20260403 | B316: SHIFT-POST-20260403 | C316: LINE-S03 | D316: 质量波动线 | E316: 产能较高但质量与节拍波动，改善后质量损失下降 | F316: 改善后 | G316: 46115 | H316: 音频模组系列 | I316: 9143 | J316: 0.643131 | K316: 1.072921 | L316: 0.974927 | M316: =J316*K316*L316 | N316: 7102 | O316: =ROUND(N316*L316,0) | P316: =IF(N316=0,0,O316/N316) | Q316: 1411 | R316: 3114 | S316: 6070 | T316: 280 | U316: 0.76 | V316: =M316-U316 | W316: =IF(OR(J316<0.65,L316<0.96,M316<0.6),"高",IF(OR(J316<0.78,K316<0.88,L316<0.98,M316<0.75),"中","低")) | X316: 团队模拟数据（基于公开单线数据派生） | Y316: https://zenodo.org/records/17855209 | Z316: SIM-v2.2-20260807-20260804 | AA316: 基于SHIFT-POST-20260403；应用质量波动线的改善后参数、确定性周期扰动及停机事件缩放

Sheet 13_多产线停机_模拟
A1: SimStopEventID | B1: SourceStopEventID | C1: SimShiftID | D1: SourceShiftID | E1: LineID | F1: 阶段 | G1: 日期 | H1: 演示产品族 | I1: 源产品编码 | J1: 源停机组 | K1: 停机类型 | L1: 源停机位置 | M1: 模拟工位 | N1: 源停机原因 | O1: 开始时间 | P1: 结束时间 | Q1: 持续时间_分钟 | R1: 缩放系数 | S1: 数据性质 | T1: 模拟版本 | U1: 来源链接 | V1: 关联模拟班次 | W1: 班次关联状态 | X1: OEE纳入状态 | Y1: 关联说明 | Z1: 是否换产事件 | AA1: 标准换产时间_分钟 | AB1: 换产超时_分钟 | AC1: 换产达标状态 | AD1: 换产规则ID | AE1: 换产标准数据性质
A2: SIM-STOP-00001 | B2: STOP-PRE-00001 | C2: LINE-S01-PRE-20250922 | D2: SHIFT-PRE-20250922 | E2: LINE-S01 | F2: 改善前 | G2: 45922 | H2: 智能终端系列 | I2: KK200-1 | J2: OPERATIONAL | K2: Planned - Not included in OEE | L2: EXTRUDER PRESS | M2: 主加工工位 | N2: NO PRODUCTION SCHEDULE | O2: 45922.469 | P2: 45922.593 | Q2: 179.6 | R2: 0.9124 | S2: 团队模拟数据（基于公开单线数据派生） | T2: SIM-v2.2-20260807-20260804 | U2: https://zenodo.org/records/17855209 | V2: LINE-S01-PRE-20250922 | W2: 已关联 | X2: 按班次口径判断 | Z2: 否
A3: SIM-STOP-00002 | B3: STOP-PRE-00001 | C3: LINE-S02-PRE-20250922 | D3: SHIFT-PRE-20250922 | E3: LINE-S02 | F3: 改善前 | G3: 45922 | H3: 视觉设备系列 | I3: KK200-1 | J3: OPERATIONAL | K3: Planned - Not included in OEE | L3: EXTRUDER PRESS | M3: 主加工工位 | N3: NO PRODUCTION SCHEDULE | O3: 45922.483 | P3: 45922.624 | Q3: 203.1 | R3: 1.0313 | S3: 团队模拟数据（基于公开单线数据派生） | T3: SIM-v2.2-20260807-20260804 | U3: https://zenodo.org/records/17855209 | V3: LINE-S02-PRE-20250922 | W3: 已关联 | X3: 按班次口径判断 | Z3: 否
